Workbook

Sheet เรื่องร้องเรียน
A1: ฐานข้อมูลดิบเรื่องร้องเรียน ปีงบประมาณ 2569 | K1: ที่อยู่ปัจจุบัน/ที่มีพฤติการณ์ | S1: รายละเอียดพฤติการณ์ | T1: พฤติการณ์ | X1: ชนิดยาเสพติดที่มีการร้องเรียน | AM1: จำนวนครั้งร้องเรียน | AN1: สน. | AO1: บก.น. | AP1: รายละเอียดพฤติการณ์ กรองแล้ว (จากพิม บก.) | AQ1: ได้รับผลการดำเนินการแล้ว | AR1: การดำเนินการ | BJ1: ชนิดยาเสพติดที่พบพฤติการณ์ | BZ1: วันที่ดำเนินการ/รายงาน | CC1: วันที่ดำเนินการ/บันทึก | CF1: รายละเอียดการดำเนินการ | CG1: เจ้าหน้าที่รัฐ | CH1: ประเภท เจ้าหน้าที่รัฐ | CI1: ประเภทสถานที่ | CL1: ซ้ำในปีงบ | CM1: แหล่งข้อมูล | CN1: ส่งหน่วยปฏิบัติ (จากพิม บก.) | CS1: หมายเหตุผลร้องเรียนซ้ำ | CT1: บำบัด/อาการทางจิต (จากพิม บก.) | CU1: เบอร์โทรศัพท์ผู้ติดต่อกลับ | CV1: ชุมชนเป้าหมาย 2567
AR2: ตรวจพิสูจน์ทราบ | AV2: ดำเนินการ (กรณีพบพฤติการณ์) | BB2: ผลการจับกุม | CI2: สถานบันเทิง/ร้านอาหาร | CJ2: วัด | CK2: สถานประกอบการ | CN2: บช.น. | CO2: บก.สส. | CP2: บก.สปพ. | CQ2: ปปส.กทม. | CR2: อื่นๆ
A3: ที่ | B3: วัน | C3: เดือน | D3: ปี | E3: กลุ่ม | F3: รหัสบุคคล/รหัสข่าว | G3: เพศ | H3: ชื่อ | I3: นามสกุล | J3: เลขที่บัตรประชาชน | K3: ที่อยู่ปัจจุบัน/ที่มีพฤติการณ์ | L3: ชุมชน | M3: แขวง | O3: รหัสชุมชน (Nispa) | P3: พิกัด X | Q3: พิกัด Y | R3: กลุ่มพื้นที่ สูตร | T3: เสพ | U3: ค้า | V3: เสพ/ค้า | W3: ผลิต | X3: ยาบ้า | Y3: ไอซ์ | Z3: ยาอี | AA3: คีตามีน | AB3: โคเคน | AC3: เฮโรอีน | AD3: มอร์ฟีน | AE3: ฝื่น | AF3: กระท่อม | AG3: กัญชา | AH3: สารระเหย | AI3: สี่คูณร้อย | AJ3: ยาใช้ในทางที่ผิด | AK3: วัตถุออกฤทธิ์ | AL3: อื่นๆ | AR3: พบพฤติการณ์ | AS3: ไม่พบพฤติการณ์ | AT3: พิสูจน์ทราบไม่ได้/ไม่พบตัว/ | AU3: เสียชีวิต | AV3: ตรวจค้น | AW3: จับกุม | AX3: หลบหนี | AY3: อยู่ระหว่างสืบสวน/ไม่แน่ใจ | AZ3: บำบัด | BA3: อื่น | BB3: จำหน่าย | BC3: เพื่อจำหน่าย | BD3: คค เพื่อเสพ | BE3: คค ซึ่งยาเสพติด | BF3: ครอบครอง | BG3: เสพ | BH3: ผลิต | BI3: ไม่ระบุ | BJ3: ยาบ้า | BK3: ไอซ์ | BL3: ยาอี | BM3: คีตามีน | BN3: โคเคน | BO3: เฮโรอีน | BP3: มอร์ฟีน | BQ3: ฝิ่น | BR3: กระท่อม | BS3: กัญชา | BT3: สารระเหย | BU3: สี่คูณร้อย | BV3: ยาใช้ในทางที่ผิด | BW3: วัตถุออกฤทธิ์ | BX3: แฮปปี้ วอเตอร์ | BY3: อื่นๆ | CV3: เป้าหมายชุมชน 357 | CW3: ชุมชนกองทุนแม่

Sheet บก.น.1-9
A1: การดำเนินงานต่อข้อร้องเรียนของประชาชน ปีงบประมาณ 2568 ห้วง (1 ตุลาคม 2566 - 4 มิถุนายน 2567)
A2: จำแนกตาม บก.น.1 - 9/สปพ.
A3: บก.น. | B3: รับเรื่อง | F3: ผลการดำเนินงานต่อข้อร้องเรียน
B4: รับ | C4: แจ้งซ้ำในปีงบ | D4: รอตรวจสอบ | E4: เท่ากับระบบDN ตัดซ้ำ | F4: พิสูจน์ทราบ | K4: การดำเนินการ (กรณีพบพฤติการณ์)
F5: พบพฤติการณ์ | G5: ไม่พบพฤติการณ์ | H5: พิสูจน์ทราบไม่ได้ /ไม่พบตัว | I5: รวม | K5: ตรวจค้น | L5: จับกุม | M5: หลบหนี | N5: อยู่ระหว่างสืบสวน | O5: บำบัด | P5: รอผล
I6: จำนวน | J6: ร้อยละ
A7: รวม | B7: =SUM(B8:B17) -> 0 | C7: =SUM(C8:C17) -> 0 | D7: =SUM(D8:D17) -> 0 | E7: =SUM(E8:E17) -> 0 | F7: =SUM(F8:F17) -> 0 | G7: =SUM(G8:G17) -> 0 | H7: =SUM(H8:H17) -> 0 | I7: =SUM(I8:I17) -> 0 | J7: =I7*100/E7 -> #DIV/0! | K7: =SUM(K8:K17) -> 0 | L7: =SUM(L8:L17) -> 0 | M7: =SUM(M8:M17) -> 0 | N7: =SUM(N8:N17) -> 0 | O7: =SUM(O8:O17) -> 0 | P7: =SUM(E7-I7) -> 0
A8: 1 | B8: =COUNTIFS(เรื่องร้องเรียน!AO:AO,"1",เรื่องร้องเรียน!E:E,"<5") -> 0 | C8: =COUNTIFS(เรื่องร้องเรียน!AO:AO,"1",เรื่องร้องเรียน!E:E,"<5",เรื่องร้องเรียน!CL:CL,"1") -> 0 | D8: =COUNTIFS(เรื่องร้องเรียน!AO:AO,"1",เรื่องร้องเรียน!E:E,"<5",เรื่องร้องเรียน!AN:AN,"") -> 0 | E8: =B8-C8-D8 -> 0 | F8: =COUNTIFS(เรื่องร้องเรียน!AO:AO,"1",เรื่องร้องเรียน!E:E,"<5",เรื่องร้องเรียน!AQ:AQ,"1",เรื่องร้องเรียน!AR:AR,"1",เรื่องร้องเรียน!CL:CL,"") -> 0 | G8: =COUNTIFS(เรื่องร้องเรียน!AO:AO,"1",เรื่องร้องเรียน!E:E,"<5",เรื่องร้องเรียน!AQ:AQ,"1",เรื่องร้องเรียน!AS:AS,"1",เรื่องร้องเรียน!CL:CL,"") -> 0 | H8: =COUNTIFS(เรื่องร้องเรียน!AO:AO,"1",เรื่องร้องเรียน!E:E,"<5",เรื่องร้องเรียน!AQ:AQ,"1",เรื่องร้องเรียน!AT:AT,"1",เรื่องร้องเรียน!CL:CL,"") -> 0 | I8: =SUM(F8:H8) -> 0 | J8: =I8*100/E8 -> #DIV/0! | K8: =COUNTIFS(เรื่องร้องเรียน!AO:AO,"1",เรื่องร้องเรียน!E:E,"<5",เรื่องร้องเรียน!AQ:AQ,"1",เรื่องร้องเรียน!AR:AR,"1",เรื่องร้องเรียน!AV:AV,"1",เรื่องร้องเรียน!CL:CL,"") -> 0 | L8: =COUNTIFS(เรื่องร้องเรียน!AO:AO,"1",เรื่องร้องเรียน!E:E,"<5",เรื่องร้องเรียน!AQ:AQ,"1",เรื่องร้องเรียน!AR:AR,"1",เรื่องร้องเรียน!AW:AW,"1",เรื่องร้องเรียน!CL:CL,"") -> 0 | M8: =COUNTIFS(เรื่องร้องเรียน!AO:AO,"1",เรื่องร้องเรียน!E:E,"<5",เรื่องร้องเรียน!AQ:AQ,"1",เรื่องร้องเรียน!AR:AR,"1",เรื่องร้องเรียน!AX:AX,"1",เรื่องร้องเรียน!CL:CL,"") -> 0 | N8: =COUNTIFS(เรื่องร้องเรียน!AO:AO,"1",เรื่องร้องเรียน!E:E,"<5",เรื่องร้องเรียน!AQ:AQ,"1",เรื่องร้องเรียน!AR:AR,"1",เรื่องร้องเรียน!AY:AY,"1",เรื่องร้องเรียน!CL:CL,"") -> 0 | O8: =COUNTIFS(เรื่องร้องเรียน!AO:AO,"1",เรื่องร้องเรียน!E:E,"<5",เรื่องร้องเรียน!AQ:AQ,"1",เรื่องร้องเรียน!AR:AR,"1",เรื่องร้องเรียน!AZ:AZ,"1",เรื่องร้องเรียน!CL:CL,"") -> 0 | P8: =SUM(E8-I8) -> 0
A9: 2 | B9: =COUNTIFS(เรื่องร้องเรียน!AO:AO,"2",เรื่องร้องเรียน!E:E,"<5") -> 0 | C9: =COUNTIFS(เรื่องร้องเรียน!AO:AO,"2",เรื่องร้องเรียน!E:E,"<5",เรื่องร้องเรียน!CL:CL,"1") -> 0 | D9: =COUNTIFS(เรื่องร้องเรียน!AO:AO,"2",เรื่องร้องเรียน!E:E,"<5",เรื่องร้องเรียน!AN:AN,"") -> 0 | E9: =B9-C9-D9 -> 0 | F9: =COUNTIFS(เรื่องร้องเรียน!AO:AO,"2",เรื่องร้องเรียน!E:E,"<5",เรื่องร้องเรียน!AQ:AQ,"1",เรื่องร้องเรียน!AR:AR,"1",เรื่องร้องเรียน!CL:CL,"") -> 0 | G9: =COUNTIFS(เรื่องร้องเรียน!AO:AO,"2",เรื่องร้องเรียน!E:E,"<5",เรื่องร้องเรียน!AQ:AQ,"1",เรื่องร้องเรียน!AS:AS,"1",เรื่องร้องเรียน!CL:CL,"") -> 0 | H9: =COUNTIFS(เรื่องร้องเรียน!AO:AO,"2",เรื่องร้องเรียน!E:E,"<5",เรื่องร้องเรียน!AQ:AQ,"1",เรื่องร้องเรียน!AT:AT,"1",เรื่องร้องเรียน!CL:CL,"") -> 0 | I9: =SUM(F9:H9) -> 0 | J9: =I9*100/E9 -> #DIV/0! | K9: =COUNTIFS(เรื่องร้องเรียน!AO:AO,"2",เรื่องร้องเรียน!E:E,"<5",เรื่องร้องเรียน!AQ:AQ,"1",เรื่องร้องเรียน!AR:AR,"1",เรื่องร้องเรียน!AV:AV,"1",เรื่องร้องเรียน!CL:CL,"") -> 0 | L9: =COUNTIFS(เรื่องร้องเรียน!AO:AO,"2",เรื่องร้องเรียน!E:E,"<5",เรื่องร้องเรียน!AQ:AQ,"1",เรื่องร้องเรียน!AR:AR,"1",เรื่องร้องเรียน!AW:AW,"1",เรื่องร้องเรียน!CL:CL,"") -> 0 | M9: =COUNTIFS(เรื่องร้องเรียน!AO:AO,"2",เรื่องร้องเรียน!E:E,"<5",เรื่องร้องเรียน!AQ:AQ,"1",เรื่องร้องเรียน!AR:AR,"1",เรื่องร้องเรียน!AX:AX,"1",เรื่องร้องเรียน!CL:CL,"") -> 0 | N9: =COUNTIFS(เรื่องร้องเรียน!AO:AO,"2",เรื่องร้องเรียน!E:E,"<5",เรื่องร้องเรียน!AQ:AQ,"1",เรื่องร้องเรียน!AR:AR,"1",เรื่องร้องเรียน!AY:AY,"1",เรื่องร้องเรียน!CL:CL,"") -> 0 | O9: =COUNTIFS(เรื่องร้องเรียน!AO:AO,"2",เรื่องร้องเรียน!E:E,"<5",เรื่องร้องเรียน!AQ:AQ,"1",เรื่องร้องเรียน!AR:AR,"1",เรื่องร้องเรียน!AZ:AZ,"1",เรื่องร้องเรียน!CL:CL,"") -> 0 | P9: =SUM(E9-I9) -> 0
A10: 3 | B10: =COUNTIFS(เรื่องร้องเรียน!AO:AO,"3",เรื่องร้องเรียน!E:E,"<5") -> 0 | C10: =COUNTIFS(เรื่องร้องเรียน!AO:AO,"3",เรื่องร้องเรียน!E:E,"<5",เรื่องร้องเรียน!CL:CL,"1") -> 0 | D10: =COUNTIFS(เรื่องร้องเรียน!AO:AO,"3",เรื่องร้องเรียน!E:E,"<5",เรื่องร้องเรียน!AN:AN,"") -> 0 | E10: =B10-C10-D10 -> 0 | F10: =COUNTIFS(เรื่องร้องเรียน!AO:AO,"3",เรื่องร้องเรียน!E:E,"<5",เรื่องร้องเรียน!AQ:AQ,"1",เรื่องร้องเรียน!AR:AR,"1",เรื่องร้องเรียน!CL:CL,"") -> 0 | G10: =COUNTIFS(เรื่องร้องเรียน!AO:AO,"3",เรื่องร้องเรียน!E:E,"<5",เรื่องร้องเรียน!AQ:AQ,"1",เรื่องร้องเรียน!AS:AS,"1",เรื่องร้องเรียน!CL:CL,"") -> 0 | H10: =COUNTIFS(เรื่องร้องเรียน!AO:AO,"3",เรื่องร้องเรียน!E:E,"<5",เรื่องร้องเรียน!AQ:AQ,"1",เรื่องร้องเรียน!AT:AT,"1",เรื่องร้องเรียน!CL:CL,"") -> 0 | I10: =SUM(F10:H10) -> 0 | J10: =I10*100/E10 -> #DIV/0! | K10: =COUNTIFS(เรื่องร้องเรียน!AO:AO,"3",เรื่องร้องเรียน!E:E,"<5",เรื่องร้องเรียน!AQ:AQ,"1",เรื่องร้องเรียน!AR:AR,"1",เรื่องร้องเรียน!AV:AV,"1",เรื่องร้องเรียน!CL:CL,"") -> 0 | L10: =COUNTIFS(เรื่องร้องเรียน!AO:AO,"3",เรื่องร้องเรียน!E:E,"<5",เรื่องร้องเรียน!AQ:AQ,"1",เรื่องร้องเรียน!AR:AR,"1",เรื่องร้องเรียน!AW:AW,"1",เรื่องร้องเรียน!CL:CL,"") -> 0 | M10: =COUNTIFS(เรื่องร้องเรียน!AO:AO,"3",เรื่องร้องเรียน!E:E,"<5",เรื่องร้องเรียน!AQ:AQ,"1",เรื่องร้องเรียน!AR:AR,"1",เรื่องร้องเรียน!AX:AX,"1",เรื่องร้องเรียน!CL:CL,"") -> 0 | N10: =COUNTIFS(เรื่องร้องเรียน!AO:AO,"3",เรื่องร้องเรียน!E:E,"<5",เรื่องร้องเรียน!AQ:AQ,"1",เรื่องร้องเรียน!AR:AR,"1",เรื่องร้องเรียน!AY:AY,"1",เรื่องร้องเรียน!CL:CL,"") -> 0 | O10: =COUNTIFS(เรื่องร้องเรียน!AO:AO,"3",เรื่องร้องเรียน!E:E,"<5",เรื่องร้องเรียน!AQ:AQ,"1",เรื่องร้องเรียน!AR:AR,"1",เรื่องร้องเรียน!AZ:AZ,"1",เรื่องร้องเรียน!CL:CL,"") -> 0 | P10: =SUM(E10-I10) -> 0
A11: 4 | B11: =COUNTIFS(เรื่องร้องเรียน!AO:AO,"4",เรื่องร้องเรียน!E:E,"<5") -> 0 | C11: =COUNTIFS(เรื่องร้องเรียน!AO:AO,"4",เรื่องร้องเรียน!E:E,"<5",เรื่องร้องเรียน!CL:CL,"1") -> 0 | D11: =COUNTIFS(เรื่องร้องเรียน!AO:AO,"4",เรื่องร้องเรียน!E:E,"<5",เรื่องร้องเรียน!AN:AN,"") -> 0 | E11: =B11-C11-D11 -> 0 | F11: =COUNTIFS(เรื่องร้องเรียน!AO:AO,"4",เรื่องร้องเรียน!E:E,"<5",เรื่องร้องเรียน!AQ:AQ,"1",เรื่องร้องเรียน!AR:AR,"1",เรื่องร้องเรียน!CL:CL,"") -> 0 | G11: =COUNTIFS(เรื่องร้องเรียน!AO:AO,"4",เรื่องร้องเรียน!E:E,"<5",เรื่องร้องเรียน!AQ:AQ,"1",เรื่องร้องเรียน!AS:AS,"1",เรื่องร้องเรียน!CL:CL,"") -> 0 | H11: =COUNTIFS(เรื่องร้องเรียน!AO:AO,"4",เรื่องร้องเรียน!E:E,"<5",เรื่องร้องเรียน!AQ:AQ,"1",เรื่องร้องเรียน!AT:AT,"1",เรื่องร้องเรียน!CL:CL,"") -> 0 | I11: =SUM(F11:H11) -> 0 | J11: =I11*100/E11 -> #DIV/0! | K11: =COUNTIFS(เรื่องร้องเรียน!AO:AO,"4",เรื่องร้องเรียน!E:E,"<5",เรื่องร้องเรียน!AQ:AQ,"1",เรื่องร้องเรียน!AR:AR,"1",เรื่องร้องเรียน!AV:AV,"1",เรื่องร้องเรียน!CL:CL,"") -> 0 | L11: =COUNTIFS(เรื่องร้องเรียน!AO:AO,"4",เรื่องร้องเรียน!E:E,"<5",เรื่องร้องเรียน!AQ:AQ,"1",เรื่องร้องเรียน!AR:AR,"1",เรื่องร้องเรียน!AW:AW,"1",เรื่องร้องเรียน!CL:CL,"") -> 0 | M11: =COUNTIFS(เรื่องร้องเรียน!AO:AO,"4",เรื่องร้องเรียน!E:E,"<5",เรื่องร้องเรียน!AQ:AQ,"1",เรื่องร้องเรียน!AR:AR,"1",เรื่องร้องเรียน!AX:AX,"1",เรื่องร้องเรียน!CL:CL,"") -> 0 | N11: =COUNTIFS(เรื่องร้องเรียน!AO:AO,"4",เรื่องร้องเรียน!E:E,"<5",เรื่องร้องเรียน!AQ:AQ,"1",เรื่องร้องเรียน!AR:AR,"1",เรื่องร้องเรียน!AY:AY,"1",เรื่องร้องเรียน!CL:CL,"") -> 0 | O11: =COUNTIFS(เรื่องร้องเรียน!AO:AO,"4",เรื่องร้องเรียน!E:E,"<5",เรื่องร้องเรียน!AQ:AQ,"1",เรื่องร้องเรียน!AR:AR,"1",เรื่องร้องเรียน!AZ:AZ,"1",เรื่องร้องเรียน!CL:CL,"") -> 0 | P11: =SUM(E11-I11) -> 0
A12: 5 | B12: =COUNTIFS(เรื่องร้องเรียน!AO:AO,"5",เรื่องร้องเรียน!E:E,"<5") -> 0 | C12: =COUNTIFS(เรื่องร้องเรียน!AO:AO,"5",เรื่องร้องเรียน!E:E,"<5",เรื่องร้องเรียน!CL:CL,"1") -> 0 | D12: =COUNTIFS(เรื่องร้องเรียน!AO:AO,"5",เรื่องร้องเรียน!E:E,"<5",เรื่องร้องเรียน!AN:AN,"") -> 0 | E12: =B12-C12-D12 -> 0 | F12: =COUNTIFS(เรื่องร้องเรียน!AO:AO,"5",เรื่องร้องเรียน!E:E,"<5",เรื่องร้องเรียน!AQ:AQ,"1",เรื่องร้องเรียน!AR:AR,"1",เรื่องร้องเรียน!CL:CL,"") -> 0 | G12: =COUNTIFS(เรื่องร้องเรียน!AO:AO,"5",เรื่องร้องเรียน!E:E,"<5",เรื่องร้องเรียน!AQ:AQ,"1",เรื่องร้องเรียน!AS:AS,"1",เรื่องร้องเรียน!CL:CL,"") -> 0 | H12: =COUNTIFS(เรื่องร้องเรียน!AO:AO,"5",เรื่องร้องเรียน!E:E,"<5",เรื่องร้องเรียน!AQ:AQ,"1",เรื่องร้องเรียน!AT:AT,"1",เรื่องร้องเรียน!CL:CL,"") -> 0 | I12: =SUM(F12:H12) -> 0 | J12: =I12*100/E12 -> #DIV/0! | K12: =COUNTIFS(เรื่องร้องเรียน!AO:AO,"5",เรื่องร้องเรียน!E:E,"<5",เรื่องร้องเรียน!AQ:AQ,"1",เรื่องร้องเรียน!AR:AR,"1",เรื่องร้องเรียน!AV:AV,"1",เรื่องร้องเรียน!CL:CL,"") -> 0 | L12: =COUNTIFS(เรื่องร้องเรียน!AO:AO,"5",เรื่องร้องเรียน!E:E,"<5",เรื่องร้องเรียน!AQ:AQ,"1",เรื่องร้องเรียน!AR:AR,"1",เรื่องร้องเรียน!AW:AW,"1",เรื่องร้องเรียน!CL:CL,"") -> 0 | M12: =COUNTIFS(เรื่องร้องเรียน!AO:AO,"5",เรื่องร้องเรียน!E:E,"<5",เรื่องร้องเรียน!AQ:AQ,"1",เรื่องร้องเรียน!AR:AR,"1",เรื่องร้องเรียน!AX:AX,"1",เรื่องร้องเรียน!CL:CL,"") -> 0 | N12: =COUNTIFS(เรื่องร้องเรียน!AO:AO,"5",เรื่องร้องเรียน!E:E,"<5",เรื่องร้องเรียน!AQ:AQ,"1",เรื่องร้องเรียน!AR:AR,"1",เรื่องร้องเรียน!AY:AY,"1",เรื่องร้องเรียน!CL:CL,"") -> 0 | O12: =COUNTIFS(เรื่องร้องเรียน!AO:AO,"5",เรื่องร้องเรียน!E:E,"<5",เรื่องร้องเรียน!AQ:AQ,"1",เรื่องร้องเรียน!AR:AR,"1",เรื่องร้องเรียน!AZ:AZ,"1",เรื่องร้องเรียน!CL:CL,"") -> 0 | P12: =SUM(E12-I12) -> 0
A13: 6 | B13: =COUNTIFS(เรื่องร้องเรียน!AO:AO,"6",เรื่องร้องเรียน!E:E,"<5") -> 0 | C13: =COUNTIFS(เรื่องร้องเรียน!AO:AO,"6",เรื่องร้องเรียน!E:E,"<5",เรื่องร้องเรียน!CL:CL,"1") -> 0 | D13: =COUNTIFS(เรื่องร้องเรียน!AO:AO,"6",เรื่องร้องเรียน!E:E,"<5",เรื่องร้องเรียน!AN:AN,"") -> 0 | E13: =B13-C13-D13 -> 0 | F13: =COUNTIFS(เรื่องร้องเรียน!AO:AO,"6",เรื่องร้องเรียน!E:E,"<5",เรื่องร้องเรียน!AQ:AQ,"1",เรื่องร้องเรียน!AR:AR,"1",เรื่องร้องเรียน!CL:CL,"") -> 0 | G13: =COUNTIFS(เรื่องร้องเรียน!AO:AO,"6",เรื่องร้องเรียน!E:E,"<5",เรื่องร้องเรียน!AQ:AQ,"1",เรื่องร้องเรียน!AS:AS,"1",เรื่องร้องเรียน!CL:CL,"") -> 0 | H13: =COUNTIFS(เรื่องร้องเรียน!AO:AO,"6",เรื่องร้องเรียน!E:E,"<5",เรื่องร้องเรียน!AQ:AQ,"1",เรื่องร้องเรียน!AT:AT,"1",เรื่องร้องเรียน!CL:CL,"") -> 0 | I13: =SUM(F13:H13) -> 0 | J13: =I13*100/E13 -> #DIV/0! | K13: =COUNTIFS(เรื่องร้องเรียน!AO:AO,"6",เรื่องร้องเรียน!E:E,"<5",เรื่องร้องเรียน!AQ:AQ,"1",เรื่องร้องเรียน!AR:AR,"1",เรื่องร้องเรียน!AV:AV,"1",เรื่องร้องเรียน!CL:CL,"") -> 0 | L13: =COUNTIFS(เรื่องร้องเรียน!AO:AO,"6",เรื่องร้องเรียน!E:E,"<5",เรื่องร้องเรียน!AQ:AQ,"1",เรื่องร้องเรียน!AR:AR,"1",เรื่องร้องเรียน!AW:AW,"1",เรื่องร้องเรียน!CL:CL,"") -> 0 | M13: =COUNTIFS(เรื่องร้องเรียน!AO:AO,"6",เรื่องร้องเรียน!E:E,"<5",เรื่องร้องเรียน!AQ:AQ,"1",เรื่องร้องเรียน!AR:AR,"1",เรื่องร้องเรียน!AX:AX,"1",เรื่องร้องเรียน!CL:CL,"") -> 0 | N13: =COUNTIFS(เรื่องร้องเรียน!AO:AO,"6",เรื่องร้องเรียน!E:E,"<5",เรื่องร้องเรียน!AQ:AQ,"1",เรื่องร้องเรียน!AR:AR,"1",เรื่องร้องเรียน!AY:AY,"1",เรื่องร้องเรียน!CL:CL,"") -> 0 | O13: =COUNTIFS(เรื่องร้องเรียน!AO:AO,"6",เรื่องร้องเรียน!E:E,"<5",เรื่องร้องเรียน!AQ:AQ,"1",เรื่องร้องเรียน!AR:AR,"1",เรื่องร้องเรียน!AZ:AZ,"1",เรื่องร้องเรียน!CL:CL,"") -> 0 | P13: =SUM(E13-I13) -> 0
A14: 7 | B14: =COUNTIFS(เรื่องร้องเรียน!AO:AO,"7",เรื่องร้องเรียน!E:E,"<5") -> 0 | C14: =COUNTIFS(เรื่องร้องเรียน!AO:AO,"7",เรื่องร้องเรียน!E:E,"<5",เรื่องร้องเรียน!CL:CL,"1") -> 0 | D14: =COUNTIFS(เรื่องร้องเรียน!AO:AO,"7",เรื่องร้องเรียน!E:E,"<5",เรื่องร้องเรียน!AN:AN,"") -> 0 | E14: =B14-C14-D14 -> 0 | F14: =COUNTIFS(เรื่องร้องเรียน!AO:AO,"7",เรื่องร้องเรียน!E:E,"<5",เรื่องร้องเรียน!AQ:AQ,"1",เรื่องร้องเรียน!AR:AR,"1",เรื่องร้องเรียน!CL:CL,"") -> 0 | G14: =COUNTIFS(เรื่องร้องเรียน!AO:AO,"7",เรื่องร้องเรียน!E:E,"<5",เรื่องร้องเรียน!AQ:AQ,"1",เรื่องร้องเรียน!AS:AS,"1",เรื่องร้องเรียน!CL:CL,"") -> 0 | H14: =COUNTIFS(เรื่องร้องเรียน!AO:AO,"7",เรื่องร้องเรียน!E:E,"<5",เรื่องร้องเรียน!AQ:AQ,"1",เรื่องร้องเรียน!AT:AT,"1",เรื่องร้องเรียน!CL:CL,"") -> 0 | I14: =SUM(F14:H14) -> 0 | J14: =I14*100/E14 -> #DIV/0! | K14: =COUNTIFS(เรื่องร้องเรียน!AO:AO,"7",เรื่องร้องเรียน!E:E,"<5",เรื่องร้องเรียน!AQ:AQ,"1",เรื่องร้องเรียน!AR:AR,"1",เรื่องร้องเรียน!AV:AV,"1",เรื่องร้องเรียน!CL:CL,"") -> 0 | L14: =COUNTIFS(เรื่องร้องเรียน!AO:AO,"7",เรื่องร้องเรียน!E:E,"<5",เรื่องร้องเรียน!AQ:AQ,"1",เรื่องร้องเรียน!AR:AR,"1",เรื่องร้องเรียน!AW:AW,"1",เรื่องร้องเรียน!CL:CL,"") -> 0 | M14: =COUNTIFS(เรื่องร้องเรียน!AO:AO,"7",เรื่องร้องเรียน!E:E,"<5",เรื่องร้องเรียน!AQ:AQ,"1",เรื่องร้องเรียน!AR:AR,"1",เรื่องร้องเรียน!AX:AX,"1",เรื่องร้องเรียน!CL:CL,"") -> 0 | N14: =COUNTIFS(เรื่องร้องเรียน!AO:AO,"7",เรื่องร้องเรียน!E:E,"<5",เรื่องร้องเรียน!AQ:AQ,"1",เรื่องร้องเรียน!AR:AR,"1",เรื่องร้องเรียน!AY:AY,"1",เรื่องร้องเรียน!CL:CL,"") -> 0 | O14: =COUNTIFS(เรื่องร้องเรียน!AO:AO,"7",เรื่องร้องเรียน!E:E,"<5",เรื่องร้องเรียน!AQ:AQ,"1",เรื่องร้องเรียน!AR:AR,"1",เรื่องร้องเรียน!AZ:AZ,"1",เรื่องร้องเรียน!CL:CL,"") -> 0 | P14: =SUM(E14-I14) -> 0
A15: 8 | B15: =COUNTIFS(เรื่องร้องเรียน!AO:AO,"8",เรื่องร้องเรียน!E:E,"<5") -> 0 | C15: =COUNTIFS(เรื่องร้องเรียน!AO:AO,"8",เรื่องร้องเรียน!E:E,"<5",เรื่องร้องเรียน!CL:CL,"1") -> 0 | D15: =COUNTIFS(เรื่องร้องเรียน!AO:AO,"8",เรื่องร้องเรียน!E:E,"<5",เรื่องร้องเรียน!AN:AN,"") -> 0 | E15: =B15-C15-D15 -> 0 | F15: =COUNTIFS(เรื่องร้องเรียน!AO:AO,"8",เรื่องร้องเรียน!E:E,"<5",เรื่องร้องเรียน!AQ:AQ,"1",เรื่องร้องเรียน!AR:AR,"1",เรื่องร้องเรียน!CL:CL,"") -> 0 | G15: =COUNTIFS(เรื่องร้องเรียน!AO:AO,"8",เรื่องร้องเรียน!E:E,"<5",เรื่องร้องเรียน!AQ:AQ,"1",เรื่องร้องเรียน!AS:AS,"1",เรื่องร้องเรียน!CL:CL,"") -> 0 | H15: =COUNTIFS(เรื่องร้องเรียน!AO:AO,"8",เรื่องร้องเรียน!E:E,"<5",เรื่องร้องเรียน!AQ:AQ,"1",เรื่องร้องเรียน!AT:AT,"1",เรื่องร้องเรียน!CL:CL,"") -> 0 | I15: =SUM(F15:H15) -> 0 | J15: =I15*100/E15 -> #DIV/0! | K15: =COUNTIFS(เรื่องร้องเรียน!AO:AO,"8",เรื่องร้องเรียน!E:E,"<5",เรื่องร้องเรียน!AQ:AQ,"1",เรื่องร้องเรียน!AR:AR,"1",เรื่องร้องเรียน!AV:AV,"1",เรื่องร้องเรียน!CL:CL,"") -> 0 | L15: =COUNTIFS(เรื่องร้องเรียน!AO:AO,"8",เรื่องร้องเรียน!E:E,"<5",เรื่องร้องเรียน!AQ:AQ,"1",เรื่องร้องเรียน!AR:AR,"1",เรื่องร้องเรียน!AW:AW,"1",เรื่องร้องเรียน!CL:CL,"") -> 0 | M15: =COUNTIFS(เรื่องร้องเรียน!AO:AO,"8",เรื่องร้องเรียน!E:E,"<5",เรื่องร้องเรียน!AQ:AQ,"1",เรื่องร้องเรียน!AR:AR,"1",เรื่องร้องเรียน!AX:AX,"1",เรื่องร้องเรียน!CL:CL,"") -> 0 | N15: =COUNTIFS(เรื่องร้องเรียน!AO:AO,"8",เรื่องร้องเรียน!E:E,"<5",เรื่องร้องเรียน!AQ:AQ,"1",เรื่องร้องเรียน!AR:AR,"1",เรื่องร้องเรียน!AY:AY,"1",เรื่องร้องเรียน!CL:CL,"") -> 0 | O15: =COUNTIFS(เรื่องร้องเรียน!AO:AO,"8",เรื่องร้องเรียน!E:E,"<5",เรื่องร้องเรียน!AQ:AQ,"1",เรื่องร้องเรียน!AR:AR,"1",เรื่องร้องเรียน!AZ:AZ,"1",เรื่องร้องเรียน!CL:CL,"") -> 0 | P15: =SUM(E15-I15) -> 0
A16: 9 | B16: =COUNTIFS(เรื่องร้องเรียน!AO:AO,"9",เรื่องร้องเรียน!E:E,"<5") -> 0 | C16: =COUNTIFS(เรื่องร้องเรียน!AO:AO,"9",เรื่องร้องเรียน!E:E,"<5",เรื่องร้องเรียน!CL:CL,"1") -> 0 | D16: =COUNTIFS(เรื่องร้องเรียน!AO:AO,"9",เรื่องร้องเรียน!E:E,"<5",เรื่องร้องเรียน!AN:AN,"") -> 0 | E16: =B16-C16-D16 -> 0 | F16: =COUNTIFS(เรื่องร้องเรียน!AO:AO,"9",เรื่องร้องเรียน!E:E,"<5",เรื่องร้องเรียน!AQ:AQ,"1",เรื่องร้องเรียน!AR:AR,"1",เรื่องร้องเรียน!CL:CL,"") -> 0 | G16: =COUNTIFS(เรื่องร้องเรียน!AO:AO,"9",เรื่องร้องเรียน!E:E,"<5",เรื่องร้องเรียน!AQ:AQ,"1",เรื่องร้องเรียน!AS:AS,"1",เรื่องร้องเรียน!CL:CL,"") -> 0 | H16: =COUNTIFS(เรื่องร้องเรียน!AO:AO,"9",เรื่องร้องเรียน!E:E,"<5",เรื่องร้องเรียน!AQ:AQ,"1",เรื่องร้องเรียน!AT:AT,"1",เรื่องร้องเรียน!CL:CL,"") -> 0 | I16: =SUM(F16:H16) -> 0 | J16: =I16*100/E16 -> #DIV/0! | K16: =COUNTIFS(เรื่องร้องเรียน!AO:AO,"9",เรื่องร้องเรียน!E:E,"<5",เรื่องร้องเรียน!AQ:AQ,"1",เรื่องร้องเรียน!AR:AR,"1",เรื่องร้องเรียน!AV:AV,"1",เรื่องร้องเรียน!CL:CL,"") -> 0 | L16: =COUNTIFS(เรื่องร้องเรียน!AO:AO,"9",เรื่องร้องเรียน!E:E,"<5",เรื่องร้องเรียน!AQ:AQ,"1",เรื่องร้องเรียน!AR:AR,"1",เรื่องร้องเรียน!AW:AW,"1",เรื่องร้องเรียน!CL:CL,"") -> 0 | M16: =COUNTIFS(เรื่องร้องเรียน!AO:AO,"9",เรื่องร้องเรียน!E:E,"<5",เรื่องร้องเรียน!AQ:AQ,"1",เรื่องร้องเรียน!AR:AR,"1",เรื่องร้องเรียน!AX:AX,"1",เรื่องร้องเรียน!CL:CL,"") -> 0 | N16: =COUNTIFS(เรื่องร้องเรียน!AO:AO,"9",เรื่องร้องเรียน!E:E,"<5",เรื่องร้องเรียน!AQ:AQ,"1",เรื่องร้องเรียน!AR:AR,"1",เรื่องร้องเรียน!AY:AY,"1",เรื่องร้องเรียน!CL:CL,"") -> 0 | O16: =COUNTIFS(เรื่องร้องเรียน!AO:AO,"9",เรื่องร้องเรียน!E:E,"<5",เรื่องร้องเรียน!AQ:AQ,"1",เรื่องร้องเรียน!AR:AR,"1",เรื่องร้องเรียน!AZ:AZ,"1",เรื่องร้องเรียน!CL:CL,"") -> 0 | P16: =SUM(E16-I16) -> 0
A17: สปพ. | B17: =COUNTIFS(เรื่องร้องเรียน!AO:AO,">=1",เรื่องร้องเรียน!E:E,"5") -> 0 | C17: =COUNTIFS(เรื่องร้องเรียน!AO:AO,">=1",เรื่องร้องเรียน!E:E,"5",เรื่องร้องเรียน!CL:CL,"1") -> 0 | D17: =COUNTIFS(เรื่องร้องเรียน!AO:AO,">=1",เรื่องร้องเรียน!E:E,"5",เรื่องร้องเรียน!AN:AN,"") -> 0 | E17: =B17-C17-D17 -> 0 | F17: =COUNTIFS(เรื่องร้องเรียน!AO:AO,">=1",เรื่องร้องเรียน!E:E,"5",เรื่องร้องเรียน!AQ:AQ,"1",เรื่องร้องเรียน!AR:AR,"1",เรื่องร้องเรียน!CL:CL,"") -> 0 | G17: =COUNTIFS(เรื่องร้องเรียน!AO:AO,">=1",เรื่องร้องเรียน!E:E,"5",เรื่องร้องเรียน!AQ:AQ,"1",เรื่องร้องเรียน!AS:AS,"1",เรื่องร้องเรียน!CL:CL,"") -> 0 | H17: =COUNTIFS(เรื่องร้องเรียน!AO:AO,">=1",เรื่องร้องเรียน!E:E,"5",เรื่องร้องเรียน!AQ:AQ,"1",เรื่องร้องเรียน!AT:AT,"1",เรื่องร้องเรียน!CL:CL,"") -> 0 | I17: =SUM(F17:H17) -> 0 | J17: =I17*100/E17 -> #DIV/0! | K17: =COUNTIFS(เรื่องร้องเรียน!AO:AO,">=1",เรื่องร้องเรียน!E:E,"5",เรื่องร้องเรียน!AQ:AQ,"1",เรื่องร้องเรียน!AR:AR,"1",เรื่องร้องเรียน!AV:AV,"1",เรื่องร้องเรียน!CL:CL,"") -> 0 | L17: =COUNTIFS(เรื่องร้องเรียน!AO:AO,">=1",เรื่องร้องเรียน!E:E,"5",เรื่องร้องเรียน!AQ:AQ,"1",เรื่องร้องเรียน!AR:AR,"1",เรื่องร้องเรียน!AW:AW,"1",เรื่องร้องเรียน!CL:CL,"") -> 0 | M17: =COUNTIFS(เรื่องร้องเรียน!AO:AO,">=1",เรื่องร้องเรียน!E:E,"5",เรื่องร้องเรียน!AQ:AQ,"1",เรื่องร้องเรียน!AR:AR,"1",เรื่องร้องเรียน!AX:AX,"1",เรื่องร้องเรียน!CL:CL,"") -> 0 | N17: =COUNTIFS(เรื่องร้องเรียน!AO:AO,">=1",เรื่องร้องเรียน!E:E,"5",เรื่องร้องเรียน!AQ:AQ,"1",เรื่องร้องเรียน!AR:AR,"1",เรื่องร้องเรียน!AY:AY,"1",เรื่องร้องเรียน!CL:CL,"") -> 0 | O17: =COUNTIFS(เรื่องร้องเรียน!AO:AO,">=1",เรื่องร้องเรียน!E:E,"5",เรื่องร้องเรียน!AQ:AQ,"1",เรื่องร้องเรียน!AR:AR,"1",เรื่องร้องเรียน!AZ:AZ,"1",เรื่องร้องเรียน!CL:CL,"") -> 0 | P17: =SUM(E17-I17) -> 0
AB1430: บางชัน

Sheet กลุ่ม 1-5
A1: การดำเนินงานต่อข้อร้องเรียนของประชาชน ปีงบประมาณ 2568
A2: จำแนกตาม กลุ่ม 1 - 5
A3: กลุ่ม | B3: รับเรื่อง | F3: ผลการดำเนินงานต่อข้อร้องเรียน
B4: รับ | C4: แจ้งซ้ำในปีงบ | D4: รอตรวจสอบ | E4: เท่ากับระบบDN ตัดซ้ำ | F4: พิสูจน์ทราบ | K4: การดำเนินการ (กรณีพบพฤติการณ์)
F5: พบพฤติการณ์ | G5: ไม่พบพฤติการณ์ | H5: พิสูจน์ทราบไม่ได้ /ไม่พบตัว | I5: รวม | K5: ตรวจค้น | L5: จับกุม | M5: หลบหนี | N5: อยู่ระหว่างสืบสวน | O5: บำบัด | P5: รอผล
I6: จำนวน | J6: ร้อยละ
A7: รวม | B7: =SUM(B8:B12) -> 0 | C7: =SUM(C8:C12) -> 0 | D7: =SUM(D8:D12) -> 0 | E7: =SUM(E8:E12) -> 0 | F7: =SUM(F8:F12) -> 0 | G7: =SUM(G8:G12) -> 0 | H7: =SUM(H8:H12) -> 0 | I7: =SUM(I8:I12) -> 0 | J7: =I7*100/E7 -> #DIV/0! | K7: =SUM(K8:K12) -> 0 | L7: =SUM(L8:L12) -> 0 | M7: =SUM(M8:M12) -> 0 | N7: =SUM(N8:N12) -> 0 | O7: =SUM(O8:O12) -> 0 | P7: =SUM(E7-I7) -> 0
A8: 1 | B8: =COUNTIF(เรื่องร้องเรียน!E:E,"1") -> 0 | C8: =COUNTIFS(เรื่องร้องเรียน!E:E,"1",เรื่องร้องเรียน!CL:CL,"1") -> 0 | D8: =COUNTIFS(เรื่องร้องเรียน!E:E,"1",เรื่องร้องเรียน!AN:AN,"") -> 0 | E8: =B8-C8-D8 -> 0 | F8: =COUNTIFS(เรื่องร้องเรียน!E:E,"1",เรื่องร้องเรียน!AQ:AQ,"1",เรื่องร้องเรียน!AR:AR,"1",เรื่องร้องเรียน!CL:CL,"") -> 0 | G8: =COUNTIFS(เรื่องร้องเรียน!E:E,"1",เรื่องร้องเรียน!AQ:AQ,"1",เรื่องร้องเรียน!AS:AS,"1",เรื่องร้องเรียน!CL:CL,"") -> 0 | H8: =COUNTIFS(เรื่องร้องเรียน!E:E,"1",เรื่องร้องเรียน!AQ:AQ,"1",เรื่องร้องเรียน!AT:AT,"1",เรื่องร้องเรียน!CL:CL,"") -> 0 | I8: =SUM(F8:H8) -> 0 | J8: =I8*100/E8 -> #DIV/0! | K8: =COUNTIFS(เรื่องร้องเรียน!E:E,"1",เรื่องร้องเรียน!AQ:AQ,"1",เรื่องร้องเรียน!AR:AR,"1",เรื่องร้องเรียน!AV:AV,"1",เรื่องร้องเรียน!CL:CL,"") -> 0 | L8: =COUNTIFS(เรื่องร้องเรียน!E:E,"1",เรื่องร้องเรียน!AQ:AQ,"1",เรื่องร้องเรียน!AR:AR,"1",เรื่องร้องเรียน!AW:AW,"1",เรื่องร้องเรียน!CL:CL,"") -> 0 | M8: =COUNTIFS(เรื่องร้องเรียน!E:E,"1",เรื่องร้องเรียน!AQ:AQ,"1",เรื่องร้องเรียน!AR:AR,"1",เรื่องร้องเรียน!AX:AX,"1",เรื่องร้องเรียน!CL:CL,"") -> 0 | N8: =COUNTIFS(เรื่องร้องเรียน!E:E,"1",เรื่องร้องเรียน!AQ:AQ,"1",เรื่องร้องเรียน!AR:AR,"1",เรื่องร้องเรียน!AY:AY,"1",เรื่องร้องเรียน!CL:CL,"") -> 0 | O8: =COUNTIFS(เรื่องร้องเรียน!E:E,"1",เรื่องร้องเรียน!AQ:AQ,"1",เรื่องร้องเรียน!AR:AR,"1",เรื่องร้องเรียน!AZ:AZ,"1",เรื่องร้องเรียน!CL:CL,"") -> 0 | P8: =SUM(E8-I8) -> 0
A9: 2 | B9: =COUNTIF(เรื่องร้องเรียน!E:E,"2") -> 0 | C9: =COUNTIFS(เรื่องร้องเรียน!E:E,"2",เรื่องร้องเรียน!CL:CL,"1") -> 0 | D9: =COUNTIFS(เรื่องร้องเรียน!E:E,"2",เรื่องร้องเรียน!AN:AN,"") -> 0 | E9: =B9-C9-D9 -> 0 | F9: =COUNTIFS(เรื่องร้องเรียน!E:E,"2",เรื่องร้องเรียน!AQ:AQ,"1",เรื่องร้องเรียน!AR:AR,"1",เรื่องร้องเรียน!CL:CL,"") -> 0 | G9: =COUNTIFS(เรื่องร้องเรียน!E:E,"2",เรื่องร้องเรียน!AQ:AQ,"1",เรื่องร้องเรียน!AS:AS,"1",เรื่องร้องเรียน!CL:CL,"") -> 0 | H9: =COUNTIFS(เรื่องร้องเรียน!E:E,"2",เรื่องร้องเรียน!AQ:AQ,"1",เรื่องร้องเรียน!AT:AT,"1",เรื่องร้องเรียน!CL:CL,"") -> 0 | I9: =SUM(F9:H9) -> 0 | J9: =I9*100/E9 -> #DIV/0! | K9: =COUNTIFS(เรื่องร้องเรียน!E:E,"2",เรื่องร้องเรียน!AQ:AQ,"1",เรื่องร้องเรียน!AR:AR,"1",เรื่องร้องเรียน!AV:AV,"1",เรื่องร้องเรียน!CL:CL,"") -> 0 | L9: =COUNTIFS(เรื่องร้องเรียน!E:E,"2",เรื่องร้องเรียน!AQ:AQ,"1",เรื่องร้องเรียน!AR:AR,"1",เรื่องร้องเรียน!AW:AW,"1",เรื่องร้องเรียน!CL:CL,"") -> 0 | M9: =COUNTIFS(เรื่องร้องเรียน!E:E,"2",เรื่องร้องเรียน!AQ:AQ,"1",เรื่องร้องเรียน!AR:AR,"1",เรื่องร้องเรียน!AX:AX,"1",เรื่องร้องเรียน!CL:CL,"") -> 0 | N9: =COUNTIFS(เรื่องร้องเรียน!E:E,"2",เรื่องร้องเรียน!AQ:AQ,"1",เรื่องร้องเรียน!AR:AR,"1",เรื่องร้องเรียน!AY:AY,"1",เรื่องร้องเรียน!CL:CL,"") -> 0 | O9: =COUNTIFS(เรื่องร้องเรียน!E:E,"2",เรื่องร้องเรียน!AQ:AQ,"1",เรื่องร้องเรียน!AR:AR,"1",เรื่องร้องเรียน!AZ:AZ,"1",เรื่องร้องเรียน!CL:CL,"") -> 0 | P9: =SUM(E9-I9) -> 0
A10: 3 | B10: =COUNTIF(เรื่องร้องเรียน!E:E,"3") -> 0 | C10: =COUNTIFS(เรื่องร้องเรียน!E:E,"3",เรื่องร้องเรียน!CL:CL,"1") -> 0 | D10: =COUNTIFS(เรื่องร้องเรียน!E:E,"3",เรื่องร้องเรียน!AN:AN,"") -> 0 | E10: =B10-C10-D10 -> 0 | F10: =COUNTIFS(เรื่องร้องเรียน!E:E,"3",เรื่องร้องเรียน!AQ:AQ,"1",เรื่องร้องเรียน!AR:AR,"1",เรื่องร้องเรียน!CL:CL,"") -> 0 | G10: =COUNTIFS(เรื่องร้องเรียน!E:E,"3",เรื่องร้องเรียน!AQ:AQ,"1",เรื่องร้องเรียน!AS:AS,"1",เรื่องร้องเรียน!CL:CL,"") -> 0 | H10: =COUNTIFS(เรื่องร้องเรียน!E:E,"3",เรื่องร้องเรียน!AQ:AQ,"1",เรื่องร้องเรียน!AT:AT,"1",เรื่องร้องเรียน!CL:CL,"") -> 0 | I10: =SUM(F10:H10) -> 0 | J10: =I10*100/E10 -> #DIV/0! | K10: =COUNTIFS(เรื่องร้องเรียน!E:E,"3",เรื่องร้องเรียน!AQ:AQ,"1",เรื่องร้องเรียน!AR:AR,"1",เรื่องร้องเรียน!AV:AV,"1",เรื่องร้องเรียน!CL:CL,"") -> 0 | L10: =COUNTIFS(เรื่องร้องเรียน!E:E,"3",เรื่องร้องเรียน!AQ:AQ,"1",เรื่องร้องเรียน!AR:AR,"1",เรื่องร้องเรียน!AW:AW,"1",เรื่องร้องเรียน!CL:CL,"") -> 0 | M10: =COUNTIFS(เรื่องร้องเรียน!E:E,"3",เรื่องร้องเรียน!AQ:AQ,"1",เรื่องร้องเรียน!AR:AR,"1",เรื่องร้องเรียน!AX:AX,"1",เรื่องร้องเรียน!CL:CL,"") -> 0 | N10: =COUNTIFS(เรื่องร้องเรียน!E:E,"3",เรื่องร้องเรียน!AQ:AQ,"1",เรื่องร้องเรียน!AR:AR,"1",เรื่องร้องเรียน!AY:AY,"1",เรื่องร้องเรียน!CL:CL,"") -> 0 | O10: =COUNTIFS(เรื่องร้องเรียน!E:E,"3",เรื่องร้องเรียน!AQ:AQ,"1",เรื่องร้องเรียน!AR:AR,"1",เรื่องร้องเรียน!AZ:AZ,"1",เรื่องร้องเรียน!CL:CL,"") -> 0 | P10: =SUM(E10-I10) -> 0
A11: 4 | B11: =COUNTIF(เรื่องร้องเรียน!E:E,"4") -> 0 | C11: =COUNTIFS(เรื่องร้องเรียน!E:E,"4",เรื่องร้องเรียน!CL:CL,"1") -> 0 | D11: =COUNTIFS(เรื่องร้องเรียน!E:E,"4",เรื่องร้องเรียน!AN:AN,"") -> 0 | E11: =B11-C11-D11 -> 0 | F11: =COUNTIFS(เรื่องร้องเรียน!E:E,"4",เรื่องร้องเรียน!AQ:AQ,"1",เรื่องร้องเรียน!AR:AR,"1",เรื่องร้องเรียน!CL:CL,"") -> 0 | G11: =COUNTIFS(เรื่องร้องเรียน!E:E,"4",เรื่องร้องเรียน!AQ:AQ,"1",เรื่องร้องเรียน!AS:AS,"1",เรื่องร้องเรียน!CL:CL,"") -> 0 | H11: =COUNTIFS(เรื่องร้องเรียน!E:E,"4",เรื่องร้องเรียน!AQ:AQ,"1",เรื่องร้องเรียน!AT:AT,"1",เรื่องร้องเรียน!CL:CL,"") -> 0 | I11: =SUM(F11:H11) -> 0 | J11: =I11*100/E11 -> #DIV/0! | K11: =COUNTIFS(เรื่องร้องเรียน!E:E,"4",เรื่องร้องเรียน!AQ:AQ,"1",เรื่องร้องเรียน!AR:AR,"1",เรื่องร้องเรียน!AV:AV,"1",เรื่องร้องเรียน!CL:CL,"") -> 0 | L11: =COUNTIFS(เรื่องร้องเรียน!E:E,"4",เรื่องร้องเรียน!AQ:AQ,"1",เรื่องร้องเรียน!AR:AR,"1",เรื่องร้องเรียน!AW:AW,"1",เรื่องร้องเรียน!CL:CL,"") -> 0 | M11: =COUNTIFS(เรื่องร้องเรียน!E:E,"4",เรื่องร้องเรียน!AQ:AQ,"1",เรื่องร้องเรียน!AR:AR,"1",เรื่องร้องเรียน!AX:AX,"1",เรื่องร้องเรียน!CL:CL,"") -> 0 | N11: =COUNTIFS(เรื่องร้องเรียน!E:E,"4",เรื่องร้องเรียน!AQ:AQ,"1",เรื่องร้องเรียน!AR:AR,"1",เรื่องร้องเรียน!AY:AY,"1",เรื่องร้องเรียน!CL:CL,"") -> 0 | O11: =COUNTIFS(เรื่องร้องเรียน!E:E,"4",เรื่องร้องเรียน!AQ:AQ,"1",เรื่องร้องเรียน!AR:AR,"1",เรื่องร้องเรียน!AZ:AZ,"1",เรื่องร้องเรียน!CL:CL,"") -> 0 | P11: =SUM(E11-I11) -> 0
A12: 5 | B12: =COUNTIF(เรื่องร้องเรียน!E:E,"5") -> 0 | C12: =COUNTIFS(เรื่องร้องเรียน!E:E,"5",เรื่องร้องเรียน!CL:CL,"1") -> 0 | D12: =COUNTIFS(เรื่องร้องเรียน!E:E,"5",เรื่องร้องเรียน!AN:AN,"") -> 0 | E12: =B12-C12-D12 -> 0 | F12: =COUNTIFS(เรื่องร้องเรียน!E:E,"5",เรื่องร้องเรียน!AQ:AQ,"1",เรื่องร้องเรียน!AR:AR,"1",เรื่องร้องเรียน!CL:CL,"") -> 0 | G12: =COUNTIFS(เรื่องร้องเรียน!E:E,"5",เรื่องร้องเรียน!AQ:AQ,"1",เรื่องร้องเรียน!AS:AS,"1",เรื่องร้องเรียน!CL:CL,"") -> 0 | H12: =COUNTIFS(เรื่องร้องเรียน!E:E,"5",เรื่องร้องเรียน!AQ:AQ,"1",เรื่องร้องเรียน!AT:AT,"1",เรื่องร้องเรียน!CL:CL,"") -> 0 | I12: =SUM(F12:H12) -> 0 | J12: =I12*100/E12 -> #DIV/0! | K12: =COUNTIFS(เรื่องร้องเรียน!E:E,"5",เรื่องร้องเรียน!AQ:AQ,"1",เรื่องร้องเรียน!AR:AR,"1",เรื่องร้องเรียน!AV:AV,"1",เรื่องร้องเรียน!CL:CL,"") -> 0 | L12: =COUNTIFS(เรื่องร้องเรียน!E:E,"5",เรื่องร้องเรียน!AQ:AQ,"1",เรื่องร้องเรียน!AR:AR,"1",เรื่องร้องเรียน!AW:AW,"1",เรื่องร้องเรียน!CL:CL,"") -> 0 | M12: =COUNTIFS(เรื่องร้องเรียน!E:E,"5",เรื่องร้องเรียน!AQ:AQ,"1",เรื่องร้องเรียน!AR:AR,"1",เรื่องร้องเรียน!AX:AX,"1",เรื่องร้องเรียน!CL:CL,"") -> 0 | N12: =COUNTIFS(เรื่องร้องเรียน!E:E,"5",เรื่องร้องเรียน!AQ:AQ,"1",เรื่องร้องเรียน!AR:AR,"1",เรื่องร้องเรียน!AY:AY,"1",เรื่องร้องเรียน!CL:CL,"") -> 0 | O12: =COUNTIFS(เรื่องร้องเรียน!E:E,"5",เรื่องร้องเรียน!AQ:AQ,"1",เรื่องร้องเรียน!AR:AR,"1",เรื่องร้องเรียน!AZ:AZ,"1",เรื่องร้องเรียน!CL:CL,"") -> 0 | P12: =SUM(E12-I12) -> 0
AB1430: บางชัน

Sheet กลุ่ม 1-5 - เขต
A1: การดำเนินงานต่อข้อร้องเรียนของประชาชนปีงบประมาณ 2569 ห้วง (1 ตุลาคม 2568 - 31 พฤษภาคม 2569)
A2: จำแนกตาม กลุ่ม 1 - 5/เขต
A3: เขต | B3: สน. | C3: รับเรื่อง | O3: ผลดำเนินงานต่อข้อร้องเรียน | U3: รอผล | W3: หักเรื่องซ้ำยอดรับเข้า
C4: กลุ่ม 1 | E4: กลุ่ม 2 | G4: กลุ่ม 3 | I4: กลุ่ม 4 | K4: กลุ่ม 5 | M4: รวม | O4: กลุ่ม 1 | P4: กลุ่ม 2 | Q4: กลุ่ม 3 | R4: กลุ่ม 4 | S4: กลุ่ม 5 | T4: รวม
C5: รับ | D5: ซ้ำ | E5: รับ | F5: ซ้ำ | G5: รับ | H5: ซ้ำ | I5: รับ | J5: ซ้ำ | K5: รับ | L5: ซ้ำ | M5: รับ | N5: ซ้ำ
A6: รวม | C6: =SUM(C7,C15,C21,C27,C33,C42,C48,C51,C56,C64,C70,C76,C81,C88,C95,C99,C107,C115,C121,C125,C132,C137,C140,C147,C153,C158,C164,C168,C174,C181,C187,C191,C197,C203,C208,C213,C219,C225,C232,C237,C242,C248,C255,C259,C265,C270,C276,C280,C288,C293) -> 0 | D6: =SUM(D7,D15,D21,D27,D33,D42,D48,D51,D56,D64,D70,D76,D81,D88,D95,D99,D107,D115,D121,D125,D132,D137,D140,D147,D153,D158,D164,D168,D174,D181,D187,D191,D197,D203,D208,D213,D219,D225,D232,D237,D242,D248,D255,D259,D265,D270,D276,D280,D288,D293) -> 0 | E6: =SUM(E7,E15,E21,E27,E33,E42,E48,E51,E56,E64,E70,E76,E81,E88,E95,E99,E107,E115,E121,E125,E132,E137,E140,E147,E153,E158,E164,E168,E174,E181,E187,E191,E197,E203,E208,E213,E219,E225,E232,E237,E242,E248,E255,E259,E265,E270,E276,E280,E288,E293) -> 0 | F6: =SUM(F7,F15,F21,F27,F33,F42,F48,F51,F56,F64,F70,F76,F81,F88,F95,F99,F107,F115,F121,F125,F132,F137,F140,F147,F153,F158,F164,F168,F174,F181,F187,F191,F197,F203,F208,F213,F219,F225,F232,F237,F242,F248,F255,F259,F265,F270,F276,F280,F288,F293) -> 0 | G6: =SUM(G7,G15,G21,G27,G33,G42,G48,G51,G56,G64,G70,G76,G81,G88,G95,G99,G107,G115,G121,G125,G132,G137,G140,G147,G153,G158,G164,G168,G174,G181,G187,G191,G197,G203,G208,G213,G219,G225,G232,G237,G242,G248,G255,G259,G265,G270,G276,G280,G288,G293) -> 0 | H6: =SUM(H7,H15,H21,H27,H33,H42,H48,H51,H56,H64,H70,H76,H81,H88,H95,H99,H107,H115,H121,H125,H132,H137,H140,H147,H153,H158,H164,H168,H174,H181,H187,H191,H197,H203,H208,H213,H219,H225,H232,H237,H242,H248,H255,H259,H265,H270,H276,H280,H288,H293) -> 0 | I6: =SUM(I7,I15,I21,I27,I33,I42,I48,I51,I56,I64,I70,I76,I81,I88,I95,I99,I107,I115,I121,I125,I132,I137,I140,I147,I153,I158,I164,I168,I174,I181,I187,I191,I197,I203,I208,I213,I219,I225,I232,I237,I242,I248,I255,I259,I265,I270,I276,I280,I288,I293) -> 0 | J6: =SUM(J7,J15,J21,J27,J33,J42,J48,J51,J56,J64,J70,J76,J81,J88,J95,J99,J107,J115,J121,J125,J132,J137,J140,J147,J153,J158,J164,J168,J174,J181,J187,J191,J197,J203,J208,J213,J219,J225,J232,J237,J242,J248,J255,J259,J265,J270,J276,J280,J288,J293) -> 0 | ... T6: =SUM(T7,T15,T21,T27,T33,T42,T48,T51,T56,T64,T70,T76,T81,T88,T95,T99,T107,T115,T121,T125,T132,T137,T140,T147,T153,T158,T164,T168,T174,T181,T187,T191,T197,T203,T208,T213,T219,T225,T232,T237,T242,T248,T255,T259,T265,T270,T276,T280,T288,T293) -> 0 | U6: =M6-N6-T6 -> 0 | W6: =SUM(M6-N6) -> 0
A7: คลองเตย | B7: รวม | C7: =SUM(C8:C14) -> 0 | D7: =SUM(D8:D14) -> 0 | E7: =SUM(E8:E14) -> 0 | F7: =SUM(F8:F14) -> 0 | G7: =SUM(G8:G14) -> 0 | H7: =SUM(H8:H14) -> 0 | I7: =SUM(I8:I14) -> 0 | J7: =SUM(J8:J14) -> 0 | ... T7: =SUM(T8:T14) -> 0 | U7: =M7-N7-T7 -> 0 | W7: =SUM(M7-N7) -> 0
B8: สปพ. | K8: =COUNTIFS(เรื่องร้องเรียน!E:E,"5",เรื่องร้องเรียน!N:N,"คลองเตย") -> 0 | L8: =COUNTIFS(เรื่องร้องเรียน!E:E,"5",เรื่องร้องเรียน!N:N,"คลองเตย",เรื่องร้องเรียน!CL:CL,"1") -> 0 | M8: =SUM(C8,E8,G8,I8,K8) -> 0 | N8: =SUM(D8,F8,H8,J8,L8) -> 0 | S8: =COUNTIFS(เรื่องร้องเรียน!E:E,"5",เรื่องร้องเรียน!N:N,"คลองเตย",เรื่องร้องเรียน!AQ:AQ,"1",เรื่องร้องเรียน!CL:CL,"") -> 0 | T8: =SUM(O8:S8) -> 0 | U8: =M8-N8-T8 -> 0 | V8: ลุมพินี | W8: =SUM(M8-N8) -> 0
B9: คลองตัน | C9: =COUNTIFS(เรื่องร้องเรียน!E:E,"1",เรื่องร้องเรียน!N:N,"คลองเตย",เรื่องร้องเรียน!AN:AN,"คลองตัน") -> 0 | D9: =COUNTIFS(เรื่องร้องเรียน!E:E,"1",เรื่องร้องเรียน!N:N,"คลองเตย",เรื่องร้องเรียน!AN:AN,"คลองตัน",เรื่องร้องเรียน!CL:CL,"1") -> 0 | E9: =COUNTIFS(เรื่องร้องเรียน!E:E,"2",เรื่องร้องเรียน!N:N,"คลองเตย",เรื่องร้องเรียน!AN:AN,"คลองตัน") -> 0 | F9: =COUNTIFS(เรื่องร้องเรียน!E:E,"2",เรื่องร้องเรียน!N:N,"คลองเตย",เรื่องร้องเรียน!AN:AN,"คลองตัน",เรื่องร้องเรียน!CL:CL,"1") -> 0 | G9: =COUNTIFS(เรื่องร้องเรียน!E:E,"3",เรื่องร้องเรียน!N:N,"คลองเตย",เรื่องร้องเรียน!AN:AN,"คลองตัน") -> 0 | H9: =COUNTIFS(เรื่องร้องเรียน!E:E,"3",เรื่องร้องเรียน!N:N,"คลองเตย",เรื่องร้องเรียน!AN:AN,"คลองตัน",เรื่องร้องเรียน!CL:CL,"1") -> 0 | I9: =COUNTIFS(เรื่องร้องเรียน!E:E,"4",เรื่องร้องเรียน!N:N,"คลองเตย",เรื่องร้องเรียน!AN:AN,"คลองตัน") -> 0 | J9: =COUNTIFS(เรื่องร้องเรียน!E:E,"4",เรื่องร้องเรียน!N:N,"คลองเตย",เรื่องร้องเรียน!AN:AN,"คลองตัน",เรื่องร้องเรียน!CL:CL,"1") -> 0 | M9: =SUM(C9,E9,G9,I9,K9) -> 0 | N9: =SUM(D9,F9,H9,J9,L9) -> 0 | O9: =COUNTIFS(เรื่องร้องเรียน!E:E,"1",เรื่องร้องเรียน!N:N,"คลองเตย",เรื่องร้องเรียน!AN:AN,"คลองตัน",เรื่องร้องเรียน!AQ:AQ,"1",เรื่องร้องเรียน!CL:CL,"") -> 0 | P9: =COUNTIFS(เรื่องร้องเรียน!E:E,"2",เรื่องร้องเรียน!N:N,"คลองเตย",เรื่องร้องเรียน!AN:AN,"คลองตัน",เรื่องร้องเรียน!AQ:AQ,"1",เรื่องร้องเรียน!CL:CL,"") -> 0 | Q9: =COUNTIFS(เรื่องร้องเรียน!E:E,"3",เรื่องร้องเรียน!N:N,"คลองเตย",เรื่องร้องเรียน!AN:AN,"คลองตัน",เรื่องร้องเรียน!AQ:AQ,"1",เรื่องร้องเรียน!CL:CL,"") -> 0 | R9: =COUNTIFS(เรื่องร้องเรียน!E:E,"4",เรื่องร้องเรียน!N:N,"คลองเตย",เรื่องร้องเรียน!AN:AN,"คลองตัน",เรื่องร้องเรียน!AQ:AQ,"1",เรื่องร้องเรียน!CL:CL,"") -> 0 | T9: =SUM(O9:S9) -> 0 | U9: =M9-N9-T9 -> 0 | W9: =SUM(M9-N9) -> 0 | Y9: ลุมพินี
B10: ทองหล่อ | C10: =COUNTIFS(เรื่องร้องเรียน!E:E,"1",เรื่องร้องเรียน!N:N,"คลองเตย",เรื่องร้องเรียน!AN:AN,"ทองหล่อ") -> 0 | D10: =COUNTIFS(เรื่องร้องเรียน!E:E,"1",เรื่องร้องเรียน!N:N,"คลองเตย",เรื่องร้องเรียน!AN:AN,"ทองหล่อ",เรื่องร้องเรียน!CL:CL,"1") -> 0 | E10: =COUNTIFS(เรื่องร้องเรียน!E:E,"2",เรื่องร้องเรียน!N:N,"คลองเตย",เรื่องร้องเรียน!AN:AN,"ทองหล่อ") -> 0 | F10: =COUNTIFS(เรื่องร้องเรียน!E:E,"2",เรื่องร้องเรียน!N:N,"คลองเตย",เรื่องร้องเรียน!AN:AN,"ทองหล่อ",เรื่องร้องเรียน!CL:CL,"1") -> 0 | G10: =COUNTIFS(เรื่องร้องเรียน!E:E,"3",เรื่องร้องเรียน!N:N,"คลองเตย",เรื่องร้องเรียน!AN:AN,"ทองหล่อ") -> 0 | H10: =COUNTIFS(เรื่องร้องเรียน!E:E,"3",เรื่องร้องเรียน!N:N,"คลองเตย",เรื่องร้องเรียน!AN:AN,"ทองหล่อ",เรื่องร้องเรียน!CL:CL,"1") -> 0 | I10: =COUNTIFS(เรื่องร้องเรียน!E:E,"4",เรื่องร้องเรียน!N:N,"คลองเตย",เรื่องร้องเรียน!AN:AN,"ทองหล่อ") -> 0 | J10: =COUNTIFS(เรื่องร้องเรียน!E:E,"4",เรื่องร้องเรียน!N:N,"คลองเตย",เรื่องร้องเรียน!AN:AN,"ทองหล่อ",เรื่องร้องเรียน!CL:CL,"1") -> 0 | M10: =SUM(C10,E10,G10,I10,K10) -> 0 | N10: =SUM(D10,F10,H10,J10,L10) -> 0 | O10: =COUNTIFS(เรื่องร้องเรียน!E:E,"1",เรื่องร้องเรียน!N:N,"คลองเตย",เรื่องร้องเรียน!AN:AN,"ทองหล่อ",เรื่องร้องเรียน!AQ:AQ,"1",เรื่องร้องเรียน!CL:CL,"") -> 0 | P10: =COUNTIFS(เรื่องร้องเรียน!E:E,"2",เรื่องร้องเรียน!N:N,"คลองเตย",เรื่องร้องเรียน!AN:AN,"ทองหล่อ",เรื่องร้องเรียน!AQ:AQ,"1",เรื่องร้องเรียน!CL:CL,"") -> 0 | Q10: =COUNTIFS(เรื่องร้องเรียน!E:E,"3",เรื่องร้องเรียน!N:N,"คลองเตย",เรื่องร้องเรียน!AN:AN,"ทองหล่อ",เรื่องร้องเรียน!AQ:AQ,"1",เรื่องร้องเรียน!CL:CL,"") -> 0 | R10: =COUNTIFS(เรื่องร้องเรียน!E:E,"4",เรื่องร้องเรียน!N:N,"คลองเตย",เรื่องร้องเรียน!AN:AN,"ทองหล่อ",เรื่องร้องเรียน!AQ:AQ,"1",เรื่องร้องเรียน!CL:CL,"") -> 0 | T10: =SUM(O10:S10) -> 0 | U10: =M10-N10-T10 -> 0 | W10: =SUM(M10-N10) -> 0
B11: ท่าเรือ | C11: =COUNTIFS(เรื่องร้องเรียน!E:E,"1",เรื่องร้องเรียน!N:N,"คลองเตย",เรื่องร้องเรียน!AN:AN,"ท่าเรือ") -> 0 | D11: =COUNTIFS(เรื่องร้องเรียน!E:E,"1",เรื่องร้องเรียน!N:N,"คลองเตย",เรื่องร้องเรียน!AN:AN,"ท่าเรือ",เรื่องร้องเรียน!CL:CL,"1") -> 0 | E11: =COUNTIFS(เรื่องร้องเรียน!E:E,"2",เรื่องร้องเรียน!N:N,"คลองเตย",เรื่องร้องเรียน!AN:AN,"ท่าเรือ") -> 0 | F11: =COUNTIFS(เรื่องร้องเรียน!E:E,"2",เรื่องร้องเรียน!N:N,"คลองเตย",เรื่องร้องเรียน!AN:AN,"ท่าเรือ",เรื่องร้องเรียน!CL:CL,"1") -> 0 | G11: =COUNTIFS(เรื่องร้องเรียน!E:E,"3",เรื่องร้องเรียน!N:N,"คลองเตย",เรื่องร้องเรียน!AN:AN,"ท่าเรือ") -> 0 | H11: =COUNTIFS(เรื่องร้องเรียน!E:E,"3",เรื่องร้องเรียน!N:N,"คลองเตย",เรื่องร้องเรียน!AN:AN,"ท่าเรือ",เรื่องร้องเรียน!CL:CL,"1") -> 0 | I11: =COUNTIFS(เรื่องร้องเรียน!E:E,"4",เรื่องร้องเรียน!N:N,"คลองเตย",เรื่องร้องเรียน!AN:AN,"ท่าเรือ") -> 0 | J11: =COUNTIFS(เรื่องร้องเรียน!E:E,"4",เรื่องร้องเรียน!N:N,"คลองเตย",เรื่องร้องเรียน!AN:AN,"ท่าเรือ",เรื่องร้องเรียน!CL:CL,"1") -> 0 | M11: =SUM(C11,E11,G11,I11,K11) -> 0 | N11: =SUM(D11,F11,H11,J11,L11) -> 0 | O11: =COUNTIFS(เรื่องร้องเรียน!E:E,"1",เรื่องร้องเรียน!N:N,"คลองเตย",เรื่องร้องเรียน!AN:AN,"ท่าเรือ",เรื่องร้องเรียน!AQ:AQ,"1",เรื่องร้องเรียน!CL:CL,"") -> 0 | P11: =COUNTIFS(เรื่องร้องเรียน!E:E,"2",เรื่องร้องเรียน!N:N,"คลองเตย",เรื่องร้องเรียน!AN:AN,"ท่าเรือ",เรื่องร้องเรียน!AQ:AQ,"1",เรื่องร้องเรียน!CL:CL,"") -> 0 | Q11: =COUNTIFS(เรื่องร้องเรียน!E:E,"3",เรื่องร้องเรียน!N:N,"คลองเตย",เรื่องร้องเรียน!AN:AN,"ท่าเรือ",เรื่องร้องเรียน!AQ:AQ,"1",เรื่องร้องเรียน!CL:CL,"") -> 0 | R11: =COUNTIFS(เรื่องร้องเรียน!E:E,"4",เรื่องร้องเรียน!N:N,"คลองเตย",เรื่องร้องเรียน!AN:AN,"ท่าเรือ",เรื่องร้องเรียน!AQ:AQ,"1",เรื่องร้องเรียน!CL:CL,"") -> 0 | T11: =SUM(O11:S11) -> 0 | U11: =M11-N11-T11 -> 0 | W11: =SUM(M11-N11) -> 0
B12: ทุ่งมหาเมฆ | C12: =COUNTIFS(เรื่องร้องเรียน!E:E,"1",เรื่องร้องเรียน!N:N,"คลองเตย",เรื่องร้องเรียน!AN:AN,"ทุ่งมหาเมฆ") -> 0 | D12: =COUNTIFS(เรื่องร้องเรียน!E:E,"1",เรื่องร้องเรียน!N:N,"คลองเตย",เรื่องร้องเรียน!AN:AN,"ทุ่งมหาเมฆ",เรื่องร้องเรียน!CL:CL,"1") -> 0 | E12: =COUNTIFS(เรื่องร้องเรียน!E:E,"2",เรื่องร้องเรียน!N:N,"คลองเตย",เรื่องร้องเรียน!AN:AN,"ทุ่งมหาเมฆ") -> 0 | F12: =COUNTIFS(เรื่องร้องเรียน!E:E,"2",เรื่องร้องเรียน!N:N,"คลองเตย",เรื่องร้องเรียน!AN:AN,"ทุ่งมหาเมฆ",เรื่องร้องเรียน!CL:CL,"1") -> 0 | G12: =COUNTIFS(เรื่องร้องเรียน!E:E,"3",เรื่องร้องเรียน!N:N,"คลองเตย",เรื่องร้องเรียน!AN:AN,"ทุ่งมหาเมฆ") -> 0 | H12: =COUNTIFS(เรื่องร้องเรียน!E:E,"3",เรื่องร้องเรียน!N:N,"คลองเตย",เรื่องร้องเรียน!AN:AN,"ทุ่งมหาเมฆ",เรื่องร้องเรียน!CL:CL,"1") -> 0 | I12: =COUNTIFS(เรื่องร้องเรียน!E:E,"4",เรื่องร้องเรียน!N:N,"คลองเตย",เรื่องร้องเรียน!AN:AN,"ทุ่งมหาเมฆ") -> 0 | J12: =COUNTIFS(เรื่องร้องเรียน!E:E,"4",เรื่องร้องเรียน!N:N,"คลองเตย",เรื่องร้องเรียน!AN:AN,"ทุ่งมหาเมฆ",เรื่องร้องเรียน!CL:CL,"1") -> 0 | M12: =SUM(C12,E12,G12,I12,K12) -> 0 | N12: =SUM(D12,F12,H12,J12,L12) -> 0 | O12: =COUNTIFS(เรื่องร้องเรียน!E:E,"1",เรื่องร้องเรียน!N:N,"คลองเตย",เรื่องร้องเรียน!AN:AN,"ทุ่งมหาเมฆ",เรื่องร้องเรียน!AQ:AQ,"1",เรื่องร้องเรียน!CL:CL,"") -> 0 | P12: =COUNTIFS(เรื่องร้องเรียน!E:E,"2",เรื่องร้องเรียน!N:N,"คลองเตย",เรื่องร้องเรียน!AN:AN,"ทุ่งมหาเมฆ",เรื่องร้องเรียน!AQ:AQ,"1",เรื่องร้องเรียน!CL:CL,"") -> 0 | Q12: =COUNTIFS(เรื่องร้องเรียน!E:E,"3",เรื่องร้องเรียน!N:N,"คลองเตย",เรื่องร้องเรียน!AN:AN,"ทุ่งมหาเมฆ",เรื่องร้องเรียน!AQ:AQ,"1",เรื่องร้องเรียน!CL:CL,"") -> 0 | R12: =COUNTIFS(เรื่องร้องเรียน!E:E,"4",เรื่องร้องเรียน!N:N,"คลองเตย",เรื่องร้องเรียน!AN:AN,"ทุ่งมหาเมฆ",เรื่องร้องเรียน!AQ:AQ,"1",เรื่องร้องเรียน!CL:CL,"") -> 0 | T12: =SUM(O12:S12) -> 0 | U12: =M12-N12-T12 -> 0 | W12: =SUM(M12-N12) -> 0
B13: พระโขนง | C13: =COUNTIFS(เรื่องร้องเรียน!E:E,"1",เรื่องร้องเรียน!N:N,"คลองเตย",เรื่องร้องเรียน!AN:AN,"พระโขนง") -> 0 | D13: =COUNTIFS(เรื่องร้องเรียน!E:E,"1",เรื่องร้องเรียน!N:N,"คลองเตย",เรื่องร้องเรียน!AN:AN,"พระโขนง",เรื่องร้องเรียน!CL:CL,"1") -> 0 | E13: =COUNTIFS(เรื่องร้องเรียน!E:E,"2",เรื่องร้องเรียน!N:N,"คลองเตย",เรื่องร้องเรียน!AN:AN,"พระโขนง") -> 0 | F13: =COUNTIFS(เรื่องร้องเรียน!E:E,"2",เรื่องร้องเรียน!N:N,"คลองเตย",เรื่องร้องเรียน!AN:AN,"พระโขนง",เรื่องร้องเรียน!CL:CL,"1") -> 0 | G13: =COUNTIFS(เรื่องร้องเรียน!E:E,"3",เรื่องร้องเรียน!N:N,"คลองเตย",เรื่องร้องเรียน!AN:AN,"พระโขนง") -> 0 | H13: =COUNTIFS(เรื่องร้องเรียน!E:E,"3",เรื่องร้องเรียน!N:N,"คลองเตย",เรื่องร้องเรียน!AN:AN,"พระโขนง",เรื่องร้องเรียน!CL:CL,"1") -> 0 | I13: =COUNTIFS(เรื่องร้องเรียน!E:E,"4",เรื่องร้องเรียน!N:N,"คลองเตย",เรื่องร้องเรียน!AN:AN,"พระโขนง") -> 0 | J13: =COUNTIFS(เรื่องร้องเรียน!E:E,"4",เรื่องร้องเรียน!N:N,"คลองเตย",เรื่องร้องเรียน!AN:AN,"พระโขนง",เรื่องร้องเรียน!CL:CL,"1") -> 0 | M13: =SUM(C13,E13,G13,I13,K13) -> 0 | N13: =SUM(D13,F13,H13,J13,L13) -> 0 | O13: =COUNTIFS(เรื่องร้องเรียน!E:E,"1",เรื่องร้องเรียน!N:N,"คลองเตย",เรื่องร้องเรียน!AN:AN,"พระโขนง",เรื่องร้องเรียน!AQ:AQ,"1",เรื่องร้องเรียน!CL:CL,"") -> 0 | P13: =COUNTIFS(เรื่องร้องเรียน!E:E,"2",เรื่องร้องเรียน!N:N,"คลองเตย",เรื่องร้องเรียน!AN:AN,"พระโขนง",เรื่องร้องเรียน!AQ:AQ,"1",เรื่องร้องเรียน!CL:CL,"") -> 0 | Q13: =COUNTIFS(เรื่องร้องเรียน!E:E,"3",เรื่องร้องเรียน!N:N,"คลองเตย",เรื่องร้องเรียน!AN:AN,"พระโขนง",เรื่องร้องเรียน!AQ:AQ,"1",เรื่องร้องเรียน!CL:CL,"") -> 0 | R13: =COUNTIFS(เรื่องร้องเรียน!E:E,"4",เรื่องร้องเรียน!N:N,"คลองเตย",เรื่องร้องเรียน!AN:AN,"พระโขนง",เรื่องร้องเรียน!AQ:AQ,"1",เรื่องร้องเรียน!CL:CL,"") -> 0 | T13: =SUM(O13:S13) -> 0 | U13: =M13-N13-T13 -> 0 | W13: =SUM(M13-N13) -> 0
B14: ลุมพินี | C14: =COUNTIFS(เรื่องร้องเรียน!E:E,"1",เรื่องร้องเรียน!N:N,"คลองเตย",เรื่องร้องเรียน!AN:AN,"ลุมพินี") -> 0 | D14: =COUNTIFS(เรื่องร้องเรียน!E:E,"1",เรื่องร้องเรียน!N:N,"คลองเตย",เรื่องร้องเรียน!AN:AN,"ลุมพินี",เรื่องร้องเรียน!CL:CL,"1") -> 0 | E14: =COUNTIFS(เรื่องร้องเรียน!E:E,"2",เรื่องร้องเรียน!N:N,"คลองเตย",เรื่องร้องเรียน!AN:AN,"ลุมพินี") -> 0 | F14: =COUNTIFS(เรื่องร้องเรียน!E:E,"2",เรื่องร้องเรียน!N:N,"คลองเตย",เรื่องร้องเรียน!AN:AN,"ลุมพินี",เรื่องร้องเรียน!CL:CL,"1") -> 0 | G14: =COUNTIFS(เรื่องร้องเรียน!E:E,"3",เรื่องร้องเรียน!N:N,"คลองเตย",เรื่องร้องเรียน!AN:AN,"ลุมพินี") -> 0 | H14: =COUNTIFS(เรื่องร้องเรียน!E:E,"3",เรื่องร้องเรียน!N:N,"คลองเตย",เรื่องร้องเรียน!AN:AN,"ลุมพินี",เรื่องร้องเรียน!CL:CL,"1") -> 0 | I14: =COUNTIFS(เรื่องร้องเรียน!E:E,"4",เรื่องร้องเรียน!N:N,"คลองเตย",เรื่องร้องเรียน!AN:AN,"ลุมพินี") -> 0 | J14: =COUNTIFS(เรื่องร้องเรียน!E:E,"4",เรื่องร้องเรียน!N:N,"คลองเตย",เรื่องร้องเรียน!AN:AN,"ลุมพินี",เรื่องร้องเรียน!CL:CL,"1") -> 0 | M14: =SUM(C14,E14,G14,I14,K14) -> 0 | N14: =SUM(D14,F14,H14,J14,L14) -> 0 | O14: =COUNTIFS(เรื่องร้องเรียน!E:E,"1",เรื่องร้องเรียน!N:N,"คลองเตย",เรื่องร้องเรียน!AN:AN,"ลุมพินี",เรื่องร้องเรียน!AQ:AQ,"1",เรื่องร้องเรียน!CL:CL,"") -> 0 | P14: =COUNTIFS(เรื่องร้องเรียน!E:E,"2",เรื่องร้องเรียน!N:N,"คลองเตย",เรื่องร้องเรียน!AN:AN,"ลุมพินี",เรื่องร้องเรียน!AQ:AQ,"1",เรื่องร้องเรียน!CL:CL,"") -> 0 | Q14: =COUNTIFS(เรื่องร้องเรียน!E:E,"3",เรื่องร้องเรียน!N:N,"คลองเตย",เรื่องร้องเรียน!AN:AN,"ลุมพินี",เรื่องร้องเรียน!AQ:AQ,"1",เรื่องร้องเรียน!CL:CL,"") -> 0 | R14: =COUNTIFS(เรื่องร้องเรียน!E:E,"4",เรื่องร้องเรียน!N:N,"คลองเตย",เรื่องร้องเรียน!AN:AN,"ลุมพินี",เรื่องร้องเรียน!AQ:AQ,"1",เรื่องร้องเรียน!CL:CL,"") -> 0 | T14: =SUM(O14:S14) -> 0 | U14: =M14-N14-T14 -> 0 | W14: =SUM(M14-N14) -> 0
A15: คลองสาน | B15: รวม | C15: =SUM(C16:C20) -> 0 | D15: =SUM(D16:D20) -> 0 | E15: =SUM(E16:E20) -> 0 | F15: =SUM(F16:F20) -> 0 | G15: =SUM(G16:G20) -> 0 | H15: =SUM(H16:H20) -> 0 | I15: =SUM(I16:I20) -> 0 | J15: =SUM(J16:J20) -> 0 | ... T15: =SUM(T16:T20) -> 0 | U15: =M15-N15-T15 -> 0 | W15: =SUM(M15-N15) -> 0
B16: สปพ. | K16: =COUNTIFS(เรื่องร้องเรียน!E:E,"5",เรื่องร้องเรียน!N:N,"คลองสาน") -> 0 | L16: =COUNTIFS(เรื่องร้องเรียน!E:E,"5",เรื่องร้องเรียน!N:N,"คลองสาน",เรื่องร้องเรียน!CL:CL,"1") -> 0 | M16: =SUM(C16,E16,G16,I16,K16) -> 0 | N16: =SUM(D16,F16,H16,J16,L16) -> 0 | S16: =COUNTIFS(เรื่องร้องเรียน!E:E,"5",เรื่องร้องเรียน!N:N,"คลองสาน",เรื่องร้องเรียน!AQ:AQ,"1",เรื่องร้องเรียน!CL:CL,"") -> 0 | T16: =SUM(O16:S16) -> 0 | U16: =M16-N16-T16 -> 0 | W16: =SUM(M16-N16) -> 0
B17: บุปผาราม | C17: =COUNTIFS(เรื่องร้องเรียน!E:E,"1",เรื่องร้องเรียน!N:N,"คลองสาน",เรื่องร้องเรียน!AN:AN,"บุปผาราม") -> 0 | D17: =COUNTIFS(เรื่องร้องเรียน!E:E,"1",เรื่องร้องเรียน!N:N,"คลองสาน",เรื่องร้องเรียน!AN:AN,"บุปผาราม",เรื่องร้องเรียน!CL:CL,"1") -> 0 | E17: =COUNTIFS(เรื่องร้องเรียน!E:E,"2",เรื่องร้องเรียน!N:N,"คลองสาน",เรื่องร้องเรียน!AN:AN,"บุปผาราม") -> 0 | F17: =COUNTIFS(เรื่องร้องเรียน!E:E,"2",เรื่องร้องเรียน!N:N,"คลองสาน",เรื่องร้องเรียน!AN:AN,"บุปผาราม",เรื่องร้องเรียน!CL:CL,"1") -> 0 | G17: =COUNTIFS(เรื่องร้องเรียน!E:E,"3",เรื่องร้องเรียน!N:N,"คลองสาน",เรื่องร้องเรียน!AN:AN,"บุปผาราม") -> 0 | H17: =COUNTIFS(เรื่องร้องเรียน!E:E,"3",เรื่องร้องเรียน!N:N,"คลองสาน",เรื่องร้องเรียน!AN:AN,"บุปผาราม",เรื่องร้องเรียน!CL:CL,"1") -> 0 | I17: =COUNTIFS(เรื่องร้องเรียน!E:E,"4",เรื่องร้องเรียน!N:N,"คลองสาน",เรื่องร้องเรียน!AN:AN,"บุปผาราม") -> 0 | J17: =COUNTIFS(เรื่องร้องเรียน!E:E,"4",เรื่องร้องเรียน!N:N,"คลองสาน",เรื่องร้องเรียน!AN:AN,"บุปผาราม",เรื่องร้องเรียน!CL:CL,"1") -> 0 | M17: =SUM(C17,E17,G17,I17,K17) -> 0 | N17: =SUM(D17,F17,H17,J17,L17) -> 0 | O17: =COUNTIFS(เรื่องร้องเรียน!E:E,"1",เรื่องร้องเรียน!N:N,"คลองสาน",เรื่องร้องเรียน!AN:AN,"บุปผาราม",เรื่องร้องเรียน!AQ:AQ,"1",เรื่องร้องเรียน!CL:CL,"") -> 0 | P17: =COUNTIFS(เรื่องร้องเรียน!E:E,"2",เรื่องร้องเรียน!N:N,"คลองสาน",เรื่องร้องเรียน!AN:AN,"บุปผาราม",เรื่องร้องเรียน!AQ:AQ,"1",เรื่องร้องเรียน!CL:CL,"") -> 0 | Q17: =COUNTIFS(เรื่องร้องเรียน!E:E,"3",เรื่องร้องเรียน!N:N,"คลองสาน",เรื่องร้องเรียน!AN:AN,"บุปผาราม",เรื่องร้องเรียน!AQ:AQ,"1",เรื่องร้องเรียน!CL:CL,"") -> 0 | R17: =COUNTIFS(เรื่องร้องเรียน!E:E,"4",เรื่องร้องเรียน!N:N,"คลองสาน",เรื่องร้องเรียน!AN:AN,"บุปผาราม",เรื่องร้องเรียน!AQ:AQ,"1",เรื่องร้องเรียน!CL:CL,"") -> 0 | T17: =SUM(O17:S17) -> 0 | U17: =M17-N17-T17 -> 0 | V17: ปากคลองสาน | W17: =SUM(M17-N17) -> 0
B18: สมเด็จเจ้าพระยา | C18: =COUNTIFS(เรื่องร้องเรียน!E:E,"1",เรื่องร้องเรียน!N:N,"คลองสาน",เรื่องร้องเรียน!AN:AN,"สมเด็จเจ้าพระยา") -> 0 | D18: =COUNTIFS(เรื่องร้องเรียน!E:E,"1",เรื่องร้องเรียน!N:N,"คลองสาน",เรื่องร้องเรียน!AN:AN,"สมเด็จเจ้าพระยา",เรื่องร้องเรียน!CL:CL,"1") -> 0 | E18: =COUNTIFS(เรื่องร้องเรียน!E:E,"2",เรื่องร้องเรียน!N:N,"คลองสาน",เรื่องร้องเรียน!AN:AN,"สมเด็จเจ้าพระยา") -> 0 | F18: =COUNTIFS(เรื่องร้องเรียน!E:E,"2",เรื่องร้องเรียน!N:N,"คลองสาน",เรื่องร้องเรียน!AN:AN,"สมเด็จเจ้าพระยา",เรื่องร้องเรียน!CL:CL,"1") -> 0 | G18: =COUNTIFS(เรื่องร้องเรียน!E:E,"3",เรื่องร้องเรียน!N:N,"คลองสาน",เรื่องร้องเรียน!AN:AN,"สมเด็จเจ้าพระยา") -> 0 | H18: =COUNTIFS(เรื่องร้องเรียน!E:E,"3",เรื่องร้องเรียน!N:N,"คลองสาน",เรื่องร้องเรียน!AN:AN,"สมเด็จเจ้าพระยา",เรื่องร้องเรียน!CL:CL,"1") -> 0 | I18: =COUNTIFS(เรื่องร้องเรียน!E:E,"4",เรื่องร้องเรียน!N:N,"คลองสาน",เรื่องร้องเรียน!AN:AN,"สมเด็จเจ้าพระยา") -> 0 | J18: =COUNTIFS(เรื่องร้องเรียน!E:E,"4",เรื่องร้องเรียน!N:N,"คลองสาน",เรื่องร้องเรียน!AN:AN,"สมเด็จเจ้าพระยา",เรื่องร้องเรียน!CL:CL,"1") -> 0 | M18: =SUM(C18,E18,G18,I18,K18) -> 0 | N18: =SUM(D18,F18,H18,J18,L18) -> 0 | O18: =COUNTIFS(เรื่องร้องเรียน!E:E,"1",เรื่องร้องเรียน!N:N,"คลองสาน",เรื่องร้องเรียน!AN:AN,"สมเด็จเจ้าพระยา",เรื่องร้องเรียน!AQ:AQ,"1",เรื่องร้องเรียน!CL:CL,"") -> 0 | P18: =COUNTIFS(เรื่องร้องเรียน!E:E,"2",เรื่องร้องเรียน!N:N,"คลองสาน",เรื่องร้องเรียน!AN:AN,"สมเด็จเจ้าพระยา",เรื่องร้องเรียน!AQ:AQ,"1",เรื่องร้องเรียน!CL:CL,"") -> 0 | Q18: =COUNTIFS(เรื่องร้องเรียน!E:E,"3",เรื่องร้องเรียน!N:N,"คลองสาน",เรื่องร้องเรียน!AN:AN,"สมเด็จเจ้าพระยา",เรื่องร้องเรียน!AQ:AQ,"1",เรื่องร้องเรียน!CL:CL,"") -> 0 | R18: =COUNTIFS(เรื่องร้องเรียน!E:E,"4",เรื่องร้องเรียน!N:N,"คลองสาน",เรื่องร้องเรียน!AN:AN,"สมเด็จเจ้าพระยา",เรื่องร้องเรียน!AQ:AQ,"1",เรื่องร้องเรียน!CL:CL,"") -> 0 | T18: =SUM(O18:S18) -> 0 | U18: =M18-N18-T18 -> 0 | W18: =SUM(M18-N18) -> 0
B19: สำเหร่ | C19: =COUNTIFS(เรื่องร้องเรียน!E:E,"1",เรื่องร้องเรียน!N:N,"คลองสาน",เรื่องร้องเรียน!AN:AN,"สำเหร่") -> 0 | D19: =COUNTIFS(เรื่องร้องเรียน!E:E,"1",เรื่องร้องเรียน!N:N,"คลองสาน",เรื่องร้องเรียน!AN:AN,"สำเหร่",เรื่องร้องเรียน!CL:CL,"1") -> 0 | E19: =COUNTIFS(เรื่องร้องเรียน!E:E,"2",เรื่องร้องเรียน!N:N,"คลองสาน",เรื่องร้องเรียน!AN:AN,"สำเหร่") -> 0 | F19: =COUNTIFS(เรื่องร้องเรียน!E:E,"2",เรื่องร้องเรียน!N:N,"คลองสาน",เรื่องร้องเรียน!AN:AN,"สำเหร่",เรื่องร้องเรียน!CL:CL,"1") -> 0 | G19: =COUNTIFS(เรื่องร้องเรียน!E:E,"3",เรื่องร้องเรียน!N:N,"คลองสาน",เรื่องร้องเรียน!AN:AN,"สำเหร่") -> 0 | H19: =COUNTIFS(เรื่องร้องเรียน!E:E,"3",เรื่องร้องเรียน!N:N,"คลองสาน",เรื่องร้องเรียน!AN:AN,"สำเหร่",เรื่องร้องเรียน!CL:CL,"1") -> 0 | I19: =COUNTIFS(เรื่องร้องเรียน!E:E,"4",เรื่องร้องเรียน!N:N,"คลองสาน",เรื่องร้องเรียน!AN:AN,"สำเหร่") -> 0 | J19: =COUNTIFS(เรื่องร้องเรียน!E:E,"4",เรื่องร้องเรียน!N:N,"คลองสาน",เรื่องร้องเรียน!AN:AN,"สำเหร่",เรื่องร้องเรียน!CL:CL,"1") -> 0 | M19: =SUM(C19,E19,G19,I19,K19) -> 0 | N19: =SUM(D19,F19,H19,J19,L19) -> 0 | O19: =COUNTIFS(เรื่องร้องเรียน!E:E,"1",เรื่องร้องเรียน!N:N,"คลองสาน",เรื่องร้องเรียน!AN:AN,"สำเหร่",เรื่องร้องเรียน!AQ:AQ,"1",เรื่องร้องเรียน!CL:CL,"") -> 0 | P19: =COUNTIFS(เรื่องร้องเรียน!E:E,"2",เรื่องร้องเรียน!N:N,"คลองสาน",เรื่องร้องเรียน!AN:AN,"สำเหร่",เรื่องร้องเรียน!AQ:AQ,"1",เรื่องร้องเรียน!CL:CL,"") -> 0 | Q19: =COUNTIFS(เรื่องร้องเรียน!E:E,"3",เรื่องร้องเรียน!N:N,"คลองสาน",เรื่องร้องเรียน!AN:AN,"สำเหร่",เรื่องร้องเรียน!AQ:AQ,"1",เรื่องร้องเรียน!CL:CL,"") -> 0 | R19: =COUNTIFS(เรื่องร้องเรียน!E:E,"4",เรื่องร้องเรียน!N:N,"คลองสาน",เรื่องร้องเรียน!AN:AN,"สำเหร่",เรื่องร้องเรียน!AQ:AQ,"1",เรื่องร้องเรียน!CL:CL,"") -> 0 | T19: =SUM(O19:S19) -> 0 | U19: =M19-N19-T19 -> 0 | W19: =SUM(M19-N19) -> 0
B20: ปากคลองสาน | C20: =COUNTIFS(เรื่องร้องเรียน!E:E,"1",เรื่องร้องเรียน!N:N,"คลองสาน",เรื่องร้องเรียน!AN:AN,"ปากคลองสาน") -> 0 | D20: =COUNTIFS(เรื่องร้องเรียน!E:E,"1",เรื่องร้องเรียน!N:N,"คลองสาน",เรื่องร้องเรียน!AN:AN,"ปากคลองสาน",เรื่องร้องเรียน!CL:CL,"1") -> 0 | E20: =COUNTIFS(เรื่องร้องเรียน!E:E,"2",เรื่องร้องเรียน!N:N,"คลองสาน",เรื่องร้องเรียน!AN:AN,"ปากคลองสาน") -> 0 | F20: =COUNTIFS(เรื่องร้องเรียน!E:E,"2",เรื่องร้องเรียน!N:N,"คลองสาน",เรื่องร้องเรียน!AN:AN,"ปากคลองสาน",เรื่องร้องเรียน!CL:CL,"1") -> 0 | G20: =COUNTIFS(เรื่องร้องเรียน!E:E,"3",เรื่องร้องเรียน!N:N,"คลองสาน",เรื่องร้องเรียน!AN:AN,"ปากคลองสาน") -> 0 | H20: =COUNTIFS(เรื่องร้องเรียน!E:E,"3",เรื่องร้องเรียน!N:N,"คลองสาน",เรื่องร้องเรียน!AN:AN,"ปากคลองสาน",เรื่องร้องเรียน!CL:CL,"1") -> 0 | I20: =COUNTIFS(เรื่องร้องเรียน!E:E,"4",เรื่องร้องเรียน!N:N,"คลองสาน",เรื่องร้องเรียน!AN:AN,"ปากคลองสาน") -> 0 | J20: =COUNTIFS(เรื่องร้องเรียน!E:E,"4",เรื่องร้องเรียน!N:N,"คลองสาน",เรื่องร้องเรียน!AN:AN,"ปากคลองสาน",เรื่องร้องเรียน!CL:CL,"1") -> 0 | M20: =SUM(C20,E20,G20,I20,K20) -> 0 | N20: =SUM(D20,F20,H20,J20,L20) -> 0 | O20: =COUNTIFS(เรื่องร้องเรียน!E:E,"1",เรื่องร้องเรียน!N:N,"คลองสาน",เรื่องร้องเรียน!AN:AN,"ปากคลองสาน",เรื่องร้องเรียน!AQ:AQ,"1",เรื่องร้องเรียน!CL:CL,"") -> 0 | P20: =COUNTIFS(เรื่องร้องเรียน!E:E,"2",เรื่องร้องเรียน!N:N,"คลองสาน",เรื่องร้องเรียน!AN:AN,"ปากคลองสาน",เรื่องร้องเรียน!AQ:AQ,"1",เรื่องร้องเรียน!CL:CL,"") -> 0 | Q20: =COUNTIFS(เรื่องร้องเรียน!E:E,"3",เรื่องร้องเรียน!N:N,"คลองสาน",เรื่องร้องเรียน!AN:AN,"ปากคลองสาน",เรื่องร้องเรียน!AQ:AQ,"1",เรื่องร้องเรียน!CL:CL,"") -> 0 | R20: =COUNTIFS(เรื่องร้องเรียน!E:E,"4",เรื่องร้องเรียน!N:N,"คลองสาน",เรื่องร้องเรียน!AN:AN,"ปากคลองสาน",เรื่องร้องเรียน!AQ:AQ,"1",เรื่องร้องเรียน!CL:CL,"") -> 0 | T20: =SUM(O20:S20) -> 0 | U20: =M20-N20-T20 -> 0 | W20: =SUM(M20-N20) -> 0
A21: คลองสามวา | B21: รวม | C21: =SUM(C22:C26 ) -> 0 | D21: =SUM(D22:D26 ) -> 0 | E21: =SUM(E22:E26 ) -> 0 | F21: =SUM(F22:F26 ) -> 0 | G21: =SUM(G22:G26 ) -> 0 | H21: =SUM(H22:H26 ) -> 0 | I21: =SUM(I22:I26 ) -> 0 | J21: =SUM(J22:J26 ) -> 0 | ... T21: =SUM(T22:T26 ) -> 0 | U21: =M21-N21-T21 -> 0 | W21: =SUM(M21-N21) -> 0
B22: สปพ. | K22: =COUNTIFS(เรื่องร้องเรียน!E:E,"5",เรื่องร้องเรียน!N:N,"คลองสามวา") -> 0 | L22: =COUNTIFS(เรื่องร้องเรียน!E:E,"5",เรื่องร้องเรียน!N:N,"คลองสามวา",เรื่องร้องเรียน!CL:CL,"1") -> 0 | M22: =SUM(C22,E22,G22,I22,K22) -> 0 | N22: =SUM(D22,F22,H22,J22,L22) -> 0 | S22: =COUNTIFS(เรื่องร้องเรียน!E:E,"5",เรื่องร้องเรียน!N:N,"คลองสามวา",เรื่องร้องเรียน!AQ:AQ,"1",เรื่องร้องเรียน!CL:CL,"") -> 0 | T22: =SUM(O22:S22) -> 0 | U22: =M22-N22-T22 -> 0 | W22: =SUM(M22-N22) -> 0
B23: คันนายาว | C23: =COUNTIFS(เรื่องร้องเรียน!E:E,"1",เรื่องร้องเรียน!N:N,"คลองสามวา",เรื่องร้องเรียน!AN:AN,"คันนายาว") -> 0 | D23: =COUNTIFS(เรื่องร้องเรียน!E:E,"1",เรื่องร้องเรียน!N:N,"คลองสามวา",เรื่องร้องเรียน!AN:AN,"คันนายาว",เรื่องร้องเรียน!CL:CL,"1") -> 0 | E23: =COUNTIFS(เรื่องร้องเรียน!E:E,"2",เรื่องร้องเรียน!N:N,"คลองสามวา",เรื่องร้องเรียน!AN:AN,"คันนายาว") -> 0 | F23: =COUNTIFS(เรื่องร้องเรียน!E:E,"2",เรื่องร้องเรียน!N:N,"คลองสามวา",เรื่องร้องเรียน!AN:AN,"คันนายาว",เรื่องร้องเรียน!CL:CL,"1") -> 0 | G23: =COUNTIFS(เรื่องร้องเรียน!E:E,"3",เรื่องร้องเรียน!N:N,"คลองสามวา",เรื่องร้องเรียน!AN:AN,"คันนายาว") -> 0 | H23: =COUNTIFS(เรื่องร้องเรียน!E:E,"3",เรื่องร้องเรียน!N:N,"คลองสามวา",เรื่องร้องเรียน!AN:AN,"คันนายาว",เรื่องร้องเรียน!CL:CL,"1") -> 0 | I23: =COUNTIFS(เรื่องร้องเรียน!E:E,"4",เรื่องร้องเรียน!N:N,"คลองสามวา",เรื่องร้องเรียน!AN:AN,"คันนายาว") -> 0 | J23: =COUNTIFS(เรื่องร้องเรียน!E:E,"4",เรื่องร้องเรียน!N:N,"คลองสามวา",เรื่องร้องเรียน!AN:AN,"คันนายาว",เรื่องร้องเรียน!CL:CL,"1") -> 0 | M23: =SUM(C23,E23,G23,I23,K23) -> 0 | N23: =SUM(D23,F23,H23,J23,L23) -> 0 | O23: =COUNTIFS(เรื่องร้องเรียน!E:E,"1",เรื่องร้องเรียน!N:N,"คลองสามวา",เรื่องร้องเรียน!AN:AN,"คันนายาว",เรื่องร้องเรียน!AQ:AQ,"1",เรื่องร้องเรียน!CL:CL,"") -> 0 | P23: =COUNTIFS(เรื่องร้องเรียน!E:E,"2",เรื่องร้องเรียน!N:N,"คลองสามวา",เรื่องร้องเรียน!AN:AN,"คันนายาว",เรื่องร้องเรียน!AQ:AQ,"1",เรื่องร้องเรียน!CL:CL,"") -> 0 | Q23: =COUNTIFS(เรื่องร้องเรียน!E:E,"3",เรื่องร้องเรียน!N:N,"คลองสามวา",เรื่องร้องเรียน!AN:AN,"คันนายาว",เรื่องร้องเรียน!AQ:AQ,"1",เรื่องร้องเรียน!CL:CL,"") -> 0 | R23: =COUNTIFS(เรื่องร้องเรียน!E:E,"4",เรื่องร้องเรียน!N:N,"คลองสามวา",เรื่องร้องเรียน!AN:AN,"คันนายาว",เรื่องร้องเรียน!AQ:AQ,"1",เรื่องร้องเรียน!CL:CL,"") -> 0 | T23: =SUM(O23:S23) -> 0 | U23: =M23-N23-T23 -> 0 | W23: =SUM(M23-N23) -> 0
B24: นิมิตรใหม่ | C24: =COUNTIFS(เรื่องร้องเรียน!E:E,"1",เรื่องร้องเรียน!N:N,"คลองสามวา",เรื่องร้องเรียน!AN:AN,"นิมิตรใหม่") -> 0 | D24: =COUNTIFS(เรื่องร้องเรียน!E:E,"1",เรื่องร้องเรียน!N:N,"คลองสามวา",เรื่องร้องเรียน!AN:AN,"นิมิตรใหม่",เรื่องร้องเรียน!CL:CL,"1") -> 0 | E24: =COUNTIFS(เรื่องร้องเรียน!E:E,"2",เรื่องร้องเรียน!N:N,"คลองสามวา",เรื่องร้องเรียน!AN:AN,"นิมิตรใหม่") -> 0 | F24: =COUNTIFS(เรื่องร้องเรียน!E:E,"2",เรื่องร้องเรียน!N:N,"คลองสามวา",เรื่องร้องเรียน!AN:AN,"นิมิตรใหม่",เรื่องร้องเรียน!CL:CL,"1") -> 0 | G24: =COUNTIFS(เรื่องร้องเรียน!E:E,"3",เรื่องร้องเรียน!N:N,"คลองสามวา",เรื่องร้องเรียน!AN:AN,"นิมิตรใหม่") -> 0 | H24: =COUNTIFS(เรื่องร้องเรียน!E:E,"3",เรื่องร้องเรียน!N:N,"คลองสามวา",เรื่องร้องเรียน!AN:AN,"นิมิตรใหม่",เรื่องร้องเรียน!CL:CL,"1") -> 0 | I24: =COUNTIFS(เรื่องร้องเรียน!E:E,"4",เรื่องร้องเรียน!N:N,"คลองสามวา",เรื่องร้องเรียน!AN:AN,"นิมิตรใหม่") -> 0 | J24: =COUNTIFS(เรื่องร้องเรียน!E:E,"4",เรื่องร้องเรียน!N:N,"คลองสามวา",เรื่องร้องเรียน!AN:AN,"นิมิตรใหม่",เรื่องร้องเรียน!CL:CL,"1") -> 0 | M24: =SUM(C24,E24,G24,I24,K24) -> 0 | N24: =SUM(D24,F24,H24,J24,L24) -> 0 | O24: =COUNTIFS(เรื่องร้องเรียน!E:E,"1",เรื่องร้องเรียน!N:N,"คลองสามวา",เรื่องร้องเรียน!AN:AN,"นิมิตรใหม่",เรื่องร้องเรียน!AQ:AQ,"1",เรื่องร้องเรียน!CL:CL,"") -> 0 | P24: =COUNTIFS(เรื่องร้องเรียน!E:E,"2",เรื่องร้องเรียน!N:N,"คลองสามวา",เรื่องร้องเรียน!AN:AN,"นิมิตรใหม่",เรื่องร้องเรียน!AQ:AQ,"1",เรื่องร้องเรียน!CL:CL,"") -> 0 | Q24: =COUNTIFS(เรื่องร้องเรียน!E:E,"3",เรื่องร้องเรียน!N:N,"คลองสามวา",เรื่องร้องเรียน!AN:AN,"นิมิตรใหม่",เรื่องร้องเรียน!AQ:AQ,"1",เรื่องร้องเรียน!CL:CL,"") -> 0 | R24: =COUNTIFS(เรื่องร้องเรียน!E:E,"4",เรื่องร้องเรียน!N:N,"คลองสามวา",เรื่องร้องเรียน!AN:AN,"นิมิตรใหม่",เรื่องร้องเรียน!AQ:AQ,"1",เรื่องร้องเรียน!CL:CL,"") -> 0 | T24: =SUM(O24:S24) -> 0 | U24: =M24-N24-T24 -> 0 | W24: =SUM(M24-N24) -> 0
B25: บางชัน | C25: =COUNTIFS(เรื่องร้องเรียน!E:E,"1",เรื่องร้องเรียน!N:N,"คลองสามวา",เรื่องร้องเรียน!AN:AN,"บางชัน") -> 0 | D25: =COUNTIFS(เรื่องร้องเรียน!E:E,"1",เรื่องร้องเรียน!N:N,"คลองสามวา",เรื่องร้องเรียน!AN:AN,"บางชัน",เรื่องร้องเรียน!CL:CL,"1") -> 0 | E25: =COUNTIFS(เรื่องร้องเรียน!E:E,"2",เรื่องร้องเรียน!N:N,"คลองสามวา",เรื่องร้องเรียน!AN:AN,"บางชัน") -> 0 | F25: =COUNTIFS(เรื่องร้องเรียน!E:E,"2",เรื่องร้องเรียน!N:N,"คลองสามวา",เรื่องร้องเรียน!AN:AN,"บางชัน",เรื่องร้องเรียน!CL:CL,"1") -> 0 | G25: =COUNTIFS(เรื่องร้องเรียน!E:E,"3",เรื่องร้องเรียน!N:N,"คลองสามวา",เรื่องร้องเรียน!AN:AN,"บางชัน") -> 0 | H25: =COUNTIFS(เรื่องร้องเรียน!E:E,"3",เรื่องร้องเรียน!N:N,"คลองสามวา",เรื่องร้องเรียน!AN:AN,"บางชัน",เรื่องร้องเรียน!CL:CL,"1") -> 0 | I25: =COUNTIFS(เรื่องร้องเรียน!E:E,"4",เรื่องร้องเรียน!N:N,"คลองสามวา",เรื่องร้องเรียน!AN:AN,"บางชัน") -> 0 | J25: =COUNTIFS(เรื่องร้องเรียน!E:E,"4",เรื่องร้องเรียน!N:N,"คลองสามวา",เรื่องร้องเรียน!AN:AN,"บางชัน",เรื่องร้องเรียน!CL:CL,"1") -> 0 | M25: =SUM(C25,E25,G25,I25,K25) -> 0 | N25: =SUM(D25,F25,H25,J25,L25) -> 0 | O25: =COUNTIFS(เรื่องร้องเรียน!E:E,"1",เรื่องร้องเรียน!N:N,"คลองสามวา",เรื่องร้องเรียน!AN:AN,"บางชัน",เรื่องร้องเรียน!AQ:AQ,"1",เรื่องร้องเรียน!CL:CL,"") -> 0 | P25: =COUNTIFS(เรื่องร้องเรียน!E:E,"2",เรื่องร้องเรียน!N:N,"คลองสามวา",เรื่องร้องเรียน!AN:AN,"บางชัน",เรื่องร้องเรียน!AQ:AQ,"1",เรื่องร้องเรียน!CL:CL,"") -> 0 | Q25: =COUNTIFS(เรื่องร้องเรียน!E:E,"3",เรื่องร้องเรียน!N:N,"คลองสามวา",เรื่องร้องเรียน!AN:AN,"บางชัน",เรื่องร้องเรียน!AQ:AQ,"1",เรื่องร้องเรียน!CL:CL,"") -> 0 | R25: =COUNTIFS(เรื่องร้องเรียน!E:E,"4",เรื่องร้องเรียน!N:N,"คลองสามวา",เรื่องร้องเรียน!AN:AN,"บางชัน",เรื่องร้องเรียน!AQ:AQ,"1",เรื่องร้องเรียน!CL:CL,"") -> 0 | T25: =SUM(O25:S25) -> 0 | U25: =M25-N25-T25 -> 0 | W25: =SUM(M25-N25) -> 0
B26: มีนบุรี | C26: =COUNTIFS(เรื่องร้องเรียน!E:E,"1",เรื่องร้องเรียน!N:N,"คลองสามวา",เรื่องร้องเรียน!AN:AN,"มีนบุรี") -> 0 | D26: =COUNTIFS(เรื่องร้องเรียน!E:E,"1",เรื่องร้องเรียน!N:N,"คลองสามวา",เรื่องร้องเรียน!AN:AN,"มีนบุรี",เรื่องร้องเรียน!CL:CL,"1") -> 0 | E26: =COUNTIFS(เรื่องร้องเรียน!E:E,"2",เรื่องร้องเรียน!N:N,"คลองสามวา",เรื่องร้องเรียน!AN:AN,"มีนบุรี") -> 0 | F26: =COUNTIFS(เรื่องร้องเรียน!E:E,"2",เรื่องร้องเรียน!N:N,"คลองสามวา",เรื่องร้องเรียน!AN:AN,"มีนบุรี",เรื่องร้องเรียน!CL:CL,"1") -> 0 | G26: =COUNTIFS(เรื่องร้องเรียน!E:E,"3",เรื่องร้องเรียน!N:N,"คลองสามวา",เรื่องร้องเรียน!AN:AN,"มีนบุรี") -> 0 | H26: =COUNTIFS(เรื่องร้องเรียน!E:E,"3",เรื่องร้องเรียน!N:N,"คลองสามวา",เรื่องร้องเรียน!AN:AN,"มีนบุรี",เรื่องร้องเรียน!CL:CL,"1") -> 0 | I26: =COUNTIFS(เรื่องร้องเรียน!E:E,"4",เรื่องร้องเรียน!N:N,"คลองสามวา",เรื่องร้องเรียน!AN:AN,"มีนบุรี") -> 0 | J26: =COUNTIFS(เรื่องร้องเรียน!E:E,"4",เรื่องร้องเรียน!N:N,"คลองสามวา",เรื่องร้องเรียน!AN:AN,"มีนบุรี",เรื่องร้องเรียน!CL:CL,"1") -> 0 | M26: =SUM(C26,E26,G26,I26,K26) -> 0 | N26: =SUM(D26,F26,H26,J26,L26) -> 0 | O26: =COUNTIFS(เรื่องร้องเรียน!E:E,"1",เรื่องร้องเรียน!N:N,"คลองสามวา",เรื่องร้องเรียน!AN:AN,"มีนบุรี",เรื่องร้องเรียน!AQ:AQ,"1",เรื่องร้องเรียน!CL:CL,"") -> 0 | P26: =COUNTIFS(เรื่องร้องเรียน!E:E,"2",เรื่องร้องเรียน!N:N,"คลองสามวา",เรื่องร้องเรียน!AN:AN,"มีนบุรี",เรื่องร้องเรียน!AQ:AQ,"1",เรื่องร้องเรียน!CL:CL,"") -> 0 | Q26: =COUNTIFS(เรื่องร้องเรียน!E:E,"3",เรื่องร้องเรียน!N:N,"คลองสามวา",เรื่องร้องเรียน!AN:AN,"มีนบุรี",เรื่องร้องเรียน!AQ:AQ,"1",เรื่องร้องเรียน!CL:CL,"") -> 0 | R26: =COUNTIFS(เรื่องร้องเรียน!E:E,"4",เรื่องร้องเรียน!N:N,"คลองสามวา",เรื่องร้องเรียน!AN:AN,"มีนบุรี",เรื่องร้องเรียน!AQ:AQ,"1",เรื่องร้องเรียน!CL:CL,"") -> 0 | T26: =SUM(O26:S26) -> 0 | U26: =M26-N26-T26 -> 0 | W26: =SUM(M26-N26) -> 0
A27: คันนายาว | B27: รวม | C27: =SUM(C28:C32 ) -> 0 | D27: =SUM(D28:D32 ) -> 0 | E27: =SUM(E28:E32 ) -> 0 | F27: =SUM(F28:F32 ) -> 0 | G27: =SUM(G28:G32 ) -> 0 | H27: =SUM(H28:H32 ) -> 0 | I27: =SUM(I28:I32 ) -> 0 | J27: =SUM(J28:J32 ) -> 0 | ... T27: =SUM(T28:T32 ) -> 0 | U27: =M27-N27-T27 -> 0 | W27: =SUM(M27-N27) -> 0
B28: สปพ. | K28: =COUNTIFS(เรื่องร้องเรียน!E:E,"5",เรื่องร้องเรียน!N:N,"คันนายาว") -> 0 | L28: =COUNTIFS(เรื่องร้องเรียน!E:E,"5",เรื่องร้องเรียน!N:N,"คันนายาว",เรื่องร้องเรียน!CL:CL,"1") -> 0 | M28: =SUM(C28,E28,G28,I28,K28) -> 0 | N28: =SUM(D28,F28,H28,J28,L28) -> 0 | S28: =COUNTIFS(เรื่องร้องเรียน!E:E,"5",เรื่องร้องเรียน!N:N,"คันนายาว",เรื่องร้องเรียน!AQ:AQ,"1",เรื่องร้องเรียน!CL:CL,"") -> 0 | T28: =SUM(O28:S28) -> 0 | U28: =M28-N28-T28 -> 0 | W28: =SUM(M28-N28) -> 0
